Workbook

Sheet Variations
A1: Date de référence | B1: 45490 | E1: ◄ Seule case à modifier : le tableau entier se recalcule.
A2: Date cible | B2: =EDATE($B$1,-1) -> 45460 | C2: =EDATE($B$1,-2) -> 45429 | D2: =EDATE($B$1,-3) -> 45399 | E2: =EDATE($B$1,-4) -> 45368 | F2: =EDATE($B$1,-5) -> 45339 | G2: =EDATE($B$1,-6) -> 45308 | H2: =EDATE($B$1,-7) -> 45277 | I2: =EDATE($B$1,-8) -> 45247 | J2: =EDATE($B$1,-9) -> 45216 | K2: =EDATE($B$1,-10) -> 45186 | L2: =EDATE($B$1,-11) -> 45155 | M2: =EDATE($B$1,-12) -> 45124
A3: Indicateur | B3: 1 mois | C3: 2 mois | D3: 3 mois | E3: 4 mois | F3: 5 mois | G3: 6 mois | H3: 7 mois | I3: 8 mois | J3: 9 mois | K3: 10 mois | L3: 11 mois | M3: 12 mois
A4: GDP CQOQ Index | B4: =IFERROR(Valeurs!$B4-Valeurs!C4,"") -> 0 | C4: =IFERROR(Valeurs!$B4-Valeurs!D4,"") -> 0 | D4: =IFERROR(Valeurs!$B4-Valeurs!E4,"") -> 0 | E4: =IFERROR(Valeurs!$B4-Valeurs!F4,"") -> -2.1 | F4: =IFERROR(Valeurs!$B4-Valeurs!G4,"") -> -2.1 | G4: =IFERROR(Valeurs!$B4-Valeurs!H4,"") -> -2.1 | H4: =IFERROR(Valeurs!$B4-Valeurs!I4,"") -> -3.6 | I4: =IFERROR(Valeurs!$B4-Valeurs!J4,"") -> -3.6 | ... M4: =IFERROR(Valeurs!$B4-Valeurs!N4,"") -> -0.8
A5: GDP CYOY Index | B5: =IFERROR(Valeurs!$B5-Valeurs!C5,"") -> 0 | C5: =IFERROR(Valeurs!$B5-Valeurs!D5,"") -> 0 | D5: =IFERROR(Valeurs!$B5-Valeurs!E5,"") -> 0 | E5: =IFERROR(Valeurs!$B5-Valeurs!F5,"") -> -0.2 | F5: =IFERROR(Valeurs!$B5-Valeurs!G5,"") -> -0.2 | G5: =IFERROR(Valeurs!$B5-Valeurs!H5,"") -> -0.2 | H5: =IFERROR(Valeurs!$B5-Valeurs!I5,"") -> 0 | I5: =IFERROR(Valeurs!$B5-Valeurs!J5,"") -> 0 | ... M5: =IFERROR(Valeurs!$B5-Valeurs!N5,"") -> 0.5
A6: GDP CURY Index | B6: =IFERROR(Valeurs!$B6-Valeurs!C6,"") -> 0 | C6: =IFERROR(Valeurs!$B6-Valeurs!D6,"") -> 0 | D6: =IFERROR(Valeurs!$B6-Valeurs!E6,"") -> 0 | E6: =IFERROR(Valeurs!$B6-Valeurs!F6,"") -> -0.5 | F6: =IFERROR(Valeurs!$B6-Valeurs!G6,"") -> -0.5 | G6: =IFERROR(Valeurs!$B6-Valeurs!H6,"") -> -0.5 | H6: =IFERROR(Valeurs!$B6-Valeurs!I6,"") -> -0.8 | I6: =IFERROR(Valeurs!$B6-Valeurs!J6,"") -> -0.8 | ... M6: =IFERROR(Valeurs!$B6-Valeurs!N6,"") -> -0.5
A7: GDP PIQQ Index | B7: =IFERROR(Valeurs!$B7-Valeurs!C7,"") -> 0 | C7: =IFERROR(Valeurs!$B7-Valeurs!D7,"") -> 0 | D7: =IFERROR(Valeurs!$B7-Valeurs!E7,"") -> 0 | E7: =IFERROR(Valeurs!$B7-Valeurs!F7,"") -> 1.4 | F7: =IFERROR(Valeurs!$B7-Valeurs!G7,"") -> 1.4 | G7: =IFERROR(Valeurs!$B7-Valeurs!H7,"") -> 1.4 | H7: =IFERROR(Valeurs!$B7-Valeurs!I7,"") -> -0.3 | I7: =IFERROR(Valeurs!$B7-Valeurs!J7,"") -> -0.3 | ... M7: =IFERROR(Valeurs!$B7-Valeurs!N7,"") -> 1.3
A8: USURTOT Index | B8: =IFERROR(Valeurs!$B8-Valeurs!C8,"") -> 0 | C8: =IFERROR(Valeurs!$B8-Valeurs!D8,"") -> 0.1 | D8: =IFERROR(Valeurs!$B8-Valeurs!E8,"") -> 0.2 | E8: =IFERROR(Valeurs!$B8-Valeurs!F8,"") -> 0.1 | F8: =IFERROR(Valeurs!$B8-Valeurs!G8,"") -> 0.3 | G8: =IFERROR(Valeurs!$B8-Valeurs!H8,"") -> 0.3 | H8: =IFERROR(Valeurs!$B8-Valeurs!I8,"") -> 0.3 | I8: =IFERROR(Valeurs!$B8-Valeurs!J8,"") -> 0.2 | ... M8: =IFERROR(Valeurs!$B8-Valeurs!N8,"") -> 0.4
A9: NFP TCH Index | B9: =IFERROR(Valeurs!$B9-Valeurs!C9,"") -> 0 | C9: =IFERROR(Valeurs!$B9-Valeurs!D9,"") -> 107 | D9: =IFERROR(Valeurs!$B9-Valeurs!E9,"") -> -38 | E9: =IFERROR(Valeurs!$B9-Valeurs!F9,"") -> 36 | F9: =IFERROR(Valeurs!$B9-Valeurs!G9,"") -> 16 | G9: =IFERROR(Valeurs!$B9-Valeurs!H9,"") -> -18 | H9: =IFERROR(Valeurs!$B9-Valeurs!I9,"") -> 90 | I9: =IFERROR(Valeurs!$B9-Valeurs!J9,"") -> 107 | ... M9: =IFERROR(Valeurs!$B9-Valeurs!N9,"") -> 32
A10: ADP CHNG Index | B10: =IFERROR(Valeurs!$B10-Valeurs!C10,"") -> 0 | C10: =IFERROR(Valeurs!$B10-Valeurs!D10,"") -> -36 | D10: =IFERROR(Valeurs!$B10-Valeurs!E10,"") -> -59 | E10: =IFERROR(Valeurs!$B10-Valeurs!F10,"") -> -23 | F10: =IFERROR(Valeurs!$B10-Valeurs!G10,"") -> 41 | G10: =IFERROR(Valeurs!$B10-Valeurs!H10,"") -> -6 | H10: =IFERROR(Valeurs!$B10-Valeurs!I10,"") -> 48 | I10: =IFERROR(Valeurs!$B10-Valeurs!J10,"") -> 41 | ... M10: =IFERROR(Valeurs!$B10-Valeurs!N10,"") -> -391
A11: LEI WKIJ Index | B11: =IFERROR(Valeurs!$B11/Valeurs!C11-1,"") -> 0 | C11: =IFERROR(Valeurs!$B11/Valeurs!D11-1,"") -> 0 | D11: =IFERROR(Valeurs!$B11/Valeurs!E11-1,"") -> -0.01958042 | E11: =IFERROR(Valeurs!$B11/Valeurs!F11-1,"") -> 0.0086330935 | F11: =IFERROR(Valeurs!$B11/Valeurs!G11-1,"") -> 0.0038186158 | G11: =IFERROR(Valeurs!$B11/Valeurs!H11-1,"") -> 0.021865889 | H11: =IFERROR(Valeurs!$B11/Valeurs!I11-1,"") -> -0.033103448 | I11: =IFERROR(Valeurs!$B11/Valeurs!J11-1,"") -> -0.00095011876 | ... M11: =IFERROR(Valeurs!$B11/Valeurs!N11-1,"") -> -0.16481334
A12: USHEYOY Index | B12: =IFERROR(Valeurs!$B12-Valeurs!C12,"") -> 0 | C12: =IFERROR(Valeurs!$B12-Valeurs!D12,"") -> 0.1 | D12: =IFERROR(Valeurs!$B12-Valeurs!E12,"") -> 0 | E12: =IFERROR(Valeurs!$B12-Valeurs!F12,"") -> -0.3 | F12: =IFERROR(Valeurs!$B12-Valeurs!G12,"") -> -0.5 | G12: =IFERROR(Valeurs!$B12-Valeurs!H12,"") -> -0.3 | H12: =IFERROR(Valeurs!$B12-Valeurs!I12,"") -> -0.4 | I12: =IFERROR(Valeurs!$B12-Valeurs!J12,"") -> -0.4 | ... M12: =IFERROR(Valeurs!$B12-Valeurs!N12,"") -> -0.8
A13: CPI XYOY Index | B13: =IFERROR(Valeurs!$B13-Valeurs!C13,"") -> 0 | C13: =IFERROR(Valeurs!$B13-Valeurs!D13,"") -> -0.2 | D13: =IFERROR(Valeurs!$B13-Valeurs!E13,"") -> -0.4 | E13: =IFERROR(Valeurs!$B13-Valeurs!F13,"") -> -0.4 | F13: =IFERROR(Valeurs!$B13-Valeurs!G13,"") -> -0.5 | G13: =IFERROR(Valeurs!$B13-Valeurs!H13,"") -> -0.5 | H13: =IFERROR(Valeurs!$B13-Valeurs!I13,"") -> -0.6 | I13: =IFERROR(Valeurs!$B13-Valeurs!J13,"") -> -0.6 | ... M13: =IFERROR(Valeurs!$B13-Valeurs!N13,"") -> -1.4
A14: PCE CYOY Index | B14: =IFERROR(Valeurs!$B14-Valeurs!C14,"") -> 0 | C14: =IFERROR(Valeurs!$B14-Valeurs!D14,"") -> 0 | D14: =IFERROR(Valeurs!$B14-Valeurs!E14,"") -> -0.05918 | E14: =IFERROR(Valeurs!$B14-Valeurs!F14,"") -> -0.06099 | F14: =IFERROR(Valeurs!$B14-Valeurs!G14,"") -> -0.15539 | G14: =IFERROR(Valeurs!$B14-Valeurs!H14,"") -> -0.18727 | H14: =IFERROR(Valeurs!$B14-Valeurs!I14,"") -> -0.42887 | I14: =IFERROR(Valeurs!$B14-Valeurs!J14,"") -> -0.63001 | ... M14: =IFERROR(Valeurs!$B14-Valeurs!N14,"") -> -1.52642
A15: PPI XYOY Index | B15: =IFERROR(Valeurs!$B15-Valeurs!C15,"") -> 0 | C15: =IFERROR(Valeurs!$B15-Valeurs!D15,"") -> 0 | D15: =IFERROR(Valeurs!$B15-Valeurs!E15,"") -> 0 | E15: =IFERROR(Valeurs!$B15-Valeurs!F15,"") -> 0 | F15: =IFERROR(Valeurs!$B15-Valeurs!G15,"") -> 0 | G15: =IFERROR(Valeurs!$B15-Valeurs!H15,"") -> -0.4 | H15: =IFERROR(Valeurs!$B15-Valeurs!I15,"") -> -0.6 | I15: =IFERROR(Valeurs!$B15-Valeurs!J15,"") -> -0.8 | ... M15: =IFERROR(Valeurs!$B15-Valeurs!N15,"") -> -1.9
A16: IP YOY Index | B16: =IFERROR(Valeurs!$B16-Valeurs!C16,"") -> 0 | C16: =IFERROR(Valeurs!$B16-Valeurs!D16,"") -> 0 | D16: =IFERROR(Valeurs!$B16-Valeurs!E16,"") -> -0.47 | E16: =IFERROR(Valeurs!$B16-Valeurs!F16,"") -> -0.44 | F16: =IFERROR(Valeurs!$B16-Valeurs!G16,"") -> 0.35 | G16: =IFERROR(Valeurs!$B16-Valeurs!H16,"") -> -1.45 | H16: =IFERROR(Valeurs!$B16-Valeurs!I16,"") -> -0.22 | I16: =IFERROR(Valeurs!$B16-Valeurs!J16,"") -> 0.44 | ... M16: =IFERROR(Valeurs!$B16-Valeurs!N16,"") -> 0
A17: CPTICHNG Index | B17: =IFERROR(Valeurs!$B17-Valeurs!C17,"") -> 0 | C17: =IFERROR(Valeurs!$B17-Valeurs!D17,"") -> 0 | D17: =IFERROR(Valeurs!$B17-Valeurs!E17,"") -> -0.0909 | E17: =IFERROR(Valeurs!$B17-Valeurs!F17,"") -> -0.0872 | F17: =IFERROR(Valeurs!$B17-Valeurs!G17,"") -> 0.4624 | G17: =IFERROR(Valeurs!$B17-Valeurs!H17,"") -> -0.2388 | H17: =IFERROR(Valeurs!$B17-Valeurs!I17,"") -> -0.5726 | I17: =IFERROR(Valeurs!$B17-Valeurs!J17,"") -> -0.3959 | ... M17: =IFERROR(Valeurs!$B17-Valeurs!N17,"") -> -0.5391
A18: DGNOYOY Index | B18: =IFERROR(Valeurs!$B18-Valeurs!C18,"") -> 0 | C18: =IFERROR(Valeurs!$B18-Valeurs!D18,"") -> 0 | D18: =IFERROR(Valeurs!$B18-Valeurs!E18,"") -> 3.4 | E18: =IFERROR(Valeurs!$B18-Valeurs!F18,"") -> -3.3 | F18: =IFERROR(Valeurs!$B18-Valeurs!G18,"") -> 2.1 | G18: =IFERROR(Valeurs!$B18-Valeurs!H18,"") -> -2.2 | H18: =IFERROR(Valeurs!$B18-Valeurs!I18,"") -> -8.8 | I18: =IFERROR(Valeurs!$B18-Valeurs!J18,"") -> 0.5 | ... M18: =IFERROR(Valeurs!$B18-Valeurs!N18,"") -> -7.8
A19: MPMIUSCA Index | B19: =IFERROR(Valeurs!$B19-Valeurs!C19,"") -> 0 | C19: =IFERROR(Valeurs!$B19-Valeurs!D19,"") -> 3.2 | D19: =IFERROR(Valeurs!$B19-Valeurs!E19,"") -> 2.4 | E19: =IFERROR(Valeurs!$B19-Valeurs!F19,"") -> 2 | F19: =IFERROR(Valeurs!$B19-Valeurs!G19,"") -> 2.5 | G19: =IFERROR(Valeurs!$B19-Valeurs!H19,"") -> 3.6 | H19: =IFERROR(Valeurs!$B19-Valeurs!I19,"") -> 3.8 | I19: =IFERROR(Valeurs!$B19-Valeurs!J19,"") -> 3.8 | ... M19: =IFERROR(Valeurs!$B19-Valeurs!N19,"") -> 1.3
A20: NAPMPMI Index | B20: =IFERROR(Valeurs!$B20-Valeurs!C20,"") -> 0 | C20: =IFERROR(Valeurs!$B20-Valeurs!D20,"") -> -0.5 | D20: =IFERROR(Valeurs!$B20-Valeurs!E20,"") -> -1.6 | E20: =IFERROR(Valeurs!$B20-Valeurs!F20,"") -> 0.9 | F20: =IFERROR(Valeurs!$B20-Valeurs!G20,"") -> -0.4 | G20: =IFERROR(Valeurs!$B20-Valeurs!H20,"") -> 1.6 | H20: =IFERROR(Valeurs!$B20-Valeurs!I20,"") -> 2.1 | I20: =IFERROR(Valeurs!$B20-Valeurs!J20,"") -> 1.8 | ... M20: =IFERROR(Valeurs!$B20-Valeurs!N20,"") -> 2.3
A21: MPMIUSMA Index | B21: =IFERROR(Valeurs!$B21-Valeurs!C21,"") -> 0 | C21: =IFERROR(Valeurs!$B21-Valeurs!D21,"") -> 1.3 | D21: =IFERROR(Valeurs!$B21-Valeurs!E21,"") -> -0.6 | E21: =IFERROR(Valeurs!$B21-Valeurs!F21,"") -> -0.9 | F21: =IFERROR(Valeurs!$B21-Valeurs!G21,"") -> 0.6 | G21: =IFERROR(Valeurs!$B21-Valeurs!H21,"") -> 3.4 | H21: =IFERROR(Valeurs!$B21-Valeurs!I21,"") -> 1.9 | I21: =IFERROR(Valeurs!$B21-Valeurs!J21,"") -> 1.3 | ... M21: =IFERROR(Valeurs!$B21-Valeurs!N21,"") -> 5
A22: MPMIUSSA Index | B22: =IFERROR(Valeurs!$B22-Valeurs!C22,"") -> 0 | C22: =IFERROR(Valeurs!$B22-Valeurs!D22,"") -> 3.5 | D22: =IFERROR(Valeurs!$B22-Valeurs!E22,"") -> 3.1 | E22: =IFERROR(Valeurs!$B22-Valeurs!F22,"") -> 2.5 | F22: =IFERROR(Valeurs!$B22-Valeurs!G22,"") -> 2.3 | G22: =IFERROR(Valeurs!$B22-Valeurs!H22,"") -> 3.4 | H22: =IFERROR(Valeurs!$B22-Valeurs!I22,"") -> 4 | I22: =IFERROR(Valeurs!$B22-Valeurs!J22,"") -> 4.2 | ... M22: =IFERROR(Valeurs!$B22-Valeurs!N22,"") -> 0.4
A23: NAPMNMI Index | B23: =IFERROR(Valeurs!$B23-Valeurs!C23,"") -> 0 | C23: =IFERROR(Valeurs!$B23-Valeurs!D23,"") -> 4.4 | D23: =IFERROR(Valeurs!$B23-Valeurs!E23,"") -> 2.4 | E23: =IFERROR(Valeurs!$B23-Valeurs!F23,"") -> 1.2 | F23: =IFERROR(Valeurs!$B23-Valeurs!G23,"") -> 0.4 | G23: =IFERROR(Valeurs!$B23-Valeurs!H23,"") -> 3.3 | H23: =IFERROR(Valeurs!$B23-Valeurs!I23,"") -> 1.3 | I23: =IFERROR(Valeurs!$B23-Valeurs!J23,"") -> 1.9 | ... M23: =IFERROR(Valeurs!$B23-Valeurs!N23,"") -> 0.2
... A29: LEI YOY Index | B29: =IFERROR(Valeurs!$B29-Valeurs!C29,"") -> 0 | C29: =IFERROR(Valeurs!$B29-Valeurs!D29,"") -> 0 | D29: =IFERROR(Valeurs!$B29-Valeurs!E29,"") -> 0.1 | E29: =IFERROR(Valeurs!$B29-Valeurs!F29,"") -> 1 | F29: =IFERROR(Valeurs!$B29-Valeurs!G29,"") -> 1.8 | G29: =IFERROR(Valeurs!$B29-Valeurs!H29,"") -> 1.8 | H29: =IFERROR(Valeurs!$B29-Valeurs!I29,"") -> 2.2 | I29: =IFERROR(Valeurs!$B29-Valeurs!J29,"") -> 2.7 | ... M29: =IFERROR(Valeurs!$B29-Valeurs!N29,"") -> 2.7
A30: NHSPATOT Index | B30: =IFERROR(Valeurs!$B30/Valeurs!C30-1,"") -> 0 | C30: =IFERROR(Valeurs!$B30/Valeurs!D30-1,"") -> 0 | D30: =IFERROR(Valeurs!$B30/Valeurs!E30-1,"") -> -0.03030303 | E30: =IFERROR(Valeurs!$B30/Valeurs!F30-1,"") -> -0.078694818 | F30: =IFERROR(Valeurs!$B30/Valeurs!G30-1,"") -> -0.045092838 | G30: =IFERROR(Valeurs!$B30/Valeurs!H30-1,"") -> -0.058823529 | H30: =IFERROR(Valeurs!$B30/Valeurs!I30-1,"") -> -0.045092838 | I30: =IFERROR(Valeurs!$B30/Valeurs!J30-1,"") -> -0.061277705 | ... M30: =IFERROR(Valeurs!$B30/Valeurs!N30-1,"") -> -0.035498995
A31: ETSLTOTL Index | B31: =IFERROR(Valeurs!$B31/Valeurs!C31-1,"") -> 0 | C31: =IFERROR(Valeurs!$B31/Valeurs!D31-1,"") -> 0 | D31: =IFERROR(Valeurs!$B31/Valeurs!E31-1,"") -> -0.018957346 | E31: =IFERROR(Valeurs!$B31/Valeurs!F31-1,"") -> -0.054794521 | F31: =IFERROR(Valeurs!$B31/Valeurs!G31-1,"") -> 0.035 | G31: =IFERROR(Valeurs!$B31/Valeurs!H31-1,"") -> 0.067010309 | H31: =IFERROR(Valeurs!$B31/Valeurs!I31-1,"") -> 0.058823529 | I31: =IFERROR(Valeurs!$B31/Valeurs!J31-1,"") -> 0.075324675 | ... M31: =IFERROR(Valeurs!$B31/Valeurs!N31-1,"") -> 0.0072992701
A32: RSTAXMOM Index | B32: =IFERROR(Valeurs!$B32-Valeurs!C32,"") -> 0 | C32: =IFERROR(Valeurs!$B32-Valeurs!D32,"") -> 0 | D32: =IFERROR(Valeurs!$B32-Valeurs!E32,"") -> -0.7 | E32: =IFERROR(Valeurs!$B32-Valeurs!F32,"") -> -0.1 | F32: =IFERROR(Valeurs!$B32-Valeurs!G32,"") -> 1 | G32: =IFERROR(Valeurs!$B32-Valeurs!H32,"") -> -0.1 | H32: =IFERROR(Valeurs!$B32-Valeurs!I32,"") -> 0.2 | I32: =IFERROR(Valeurs!$B32-Valeurs!J32,"") -> 0.2 | ... M32: =IFERROR(Valeurs!$B32-Valeurs!N32,"") -> 0.1
A33: RSTAXYOY Index | B33: =IFERROR(Valeurs!$B33-Valeurs!C33,"") -> 0 | C33: =IFERROR(Valeurs!$B33-Valeurs!D33,"") -> 0 | D33: =IFERROR(Valeurs!$B33-Valeurs!E33,"") -> -0.4 | E33: =IFERROR(Valeurs!$B33-Valeurs!F33,"") -> 1.6 | F33: =IFERROR(Valeurs!$B33-Valeurs!G33,"") -> 2.7 | G33: =IFERROR(Valeurs!$B33-Valeurs!H33,"") -> -1 | H33: =IFERROR(Valeurs!$B33-Valeurs!I33,"") -> 0 | I33: =IFERROR(Valeurs!$B33-Valeurs!J33,"") -> 1 | ... M33: =IFERROR(Valeurs!$B33-Valeurs!N33,"") -> 2.9
A34: SAARTOTL Index | B34: =IFERROR(Valeurs!$B34/Valeurs!C34-1,"") -> 0 | C34: =IFERROR(Valeurs!$B34/Valeurs!D34-1,"") -> 0.010165184 | D34: =IFERROR(Valeurs!$B34/Valeurs!E34-1,"") -> 0.026468689 | E34: =IFERROR(Valeurs!$B34/Valeurs!F34-1,"") -> 0.0056925996 | F34: =IFERROR(Valeurs!$B34/Valeurs!G34-1,"") -> 0.06 | G34: =IFERROR(Valeurs!$B34/Valeurs!H34-1,"") -> 0.0044219836 | H34: =IFERROR(Valeurs!$B34/Valeurs!I34-1,"") -> 0.037859008 | I34: =IFERROR(Valeurs!$B34/Valeurs!J34-1,"") -> 0.025806452 | ... M34: =IFERROR(Valeurs!$B34/Valeurs!N34-1,"") -> 0.014030612
A35: PITLYOY Index | B35: =IFERROR(Valeurs!$B35-Valeurs!C35,"") -> 0 | C35: =IFERROR(Valeurs!$B35-Valeurs!D35,"") -> 0 | D35: =IFERROR(Valeurs!$B35-Valeurs!E35,"") -> 0.1 | E35: =IFERROR(Valeurs!$B35-Valeurs!F35,"") -> 0.2 | F35: =IFERROR(Valeurs!$B35-Valeurs!G35,"") -> -0.1 | G35: =IFERROR(Valeurs!$B35-Valeurs!H35,"") -> 0 | H35: =IFERROR(Valeurs!$B35-Valeurs!I35,"") -> 0.1 | I35: =IFERROR(Valeurs!$B35-Valeurs!J35,"") -> 0.2 | ... M35: =IFERROR(Valeurs!$B35-Valeurs!N35,"") -> -0.9
A36: PCE CHY% Index | B36: =IFERROR(Valeurs!$B36-Valeurs!C36,"") -> 0 | C36: =IFERROR(Valeurs!$B36-Valeurs!D36,"") -> 0 | D36: =IFERROR(Valeurs!$B36-Valeurs!E36,"") -> -0.2 | E36: =IFERROR(Valeurs!$B36-Valeurs!F36,"") -> 0.4 | F36: =IFERROR(Valeurs!$B36-Valeurs!G36,"") -> 0.7 | G36: =IFERROR(Valeurs!$B36-Valeurs!H36,"") -> -0.7 | H36: =IFERROR(Valeurs!$B36-Valeurs!I36,"") -> -0.3 | I36: =IFERROR(Valeurs!$B36-Valeurs!J36,"") -> 0.5 | ... M36: =IFERROR(Valeurs!$B36-Valeurs!N36,"") -> 0.5
A37: PCE CHNC Index | B37: =IFERROR(Valeurs!$B37-Valeurs!C37,"") -> 0 | C37: =IFERROR(Valeurs!$B37-Valeurs!D37,"") -> 0 | D37: =IFERROR(Valeurs!$B37-Valeurs!E37,"") -> -0.5 | E37: =IFERROR(Valeurs!$B37-Valeurs!F37,"") -> -0.4 | F37: =IFERROR(Valeurs!$B37-Valeurs!G37,"") -> 0.2 | G37: =IFERROR(Valeurs!$B37-Valeurs!H37,"") -> -0.6 | H37: =IFERROR(Valeurs!$B37-Valeurs!I37,"") -> -0.5 | I37: =IFERROR(Valeurs!$B37-Valeurs!J37,"") -> -0.3 | ... M37: =IFERROR(Valeurs!$B37-Valeurs!N37,"") -> -0.4
A38: CONCCONF Index | B38: =IFERROR(Valeurs!$B38-Valeurs!C38,"") -> 0 | C38: =IFERROR(Valeurs!$B38-Valeurs!D38,"") -> 4.5 | D38: =IFERROR(Valeurs!$B38-Valeurs!E38,"") -> -1.1 | E38: =IFERROR(Valeurs!$B38-Valeurs!F38,"") -> -2.8 | F38: =IFERROR(Valeurs!$B38-Valeurs!G38,"") -> -8.9 | G38: =IFERROR(Valeurs!$B38-Valeurs!H38,"") -> -6 | H38: =IFERROR(Valeurs!$B38-Valeurs!I38,"") -> 1 | I38: =IFERROR(Valeurs!$B38-Valeurs!J38,"") -> 2.9 | ... M38: =IFERROR(Valeurs!$B38-Valeurs!N38,"") -> -8.1
A39: CONSSENT Index | B39: =IFERROR(Valeurs!$B39-Valeurs!C39,"") -> -3.5 | C39: =IFERROR(Valeurs!$B39-Valeurs!D39,"") -> -11.6 | D39: =IFERROR(Valeurs!$B39-Valeurs!E39,"") -> -13.8 | E39: =IFERROR(Valeurs!$B39-Valeurs!F39,"") -> -11.3 | F39: =IFERROR(Valeurs!$B39-Valeurs!G39,"") -> -13.4 | G39: =IFERROR(Valeurs!$B39-Valeurs!H39,"") -> -4.1 | H39: =IFERROR(Valeurs!$B39-Valeurs!I39,"") -> 4.3 | I39: =IFERROR(Valeurs!$B39-Valeurs!J39,"") -> 1.8 | ... M39: =IFERROR(Valeurs!$B39-Valeurs!N39,"") -> 1.4
A40: SPX INDEX | B40: =IFERROR(Valeurs!$B40/Valeurs!C40-1,"") -> 0.021018667 | C40: =IFERROR(Valeurs!$B40/Valeurs!D40-1,"") -> 0.053740428 | D40: =IFERROR(Valeurs!$B40/Valeurs!E40-1,"") -> 0.11271134 | E40: =IFERROR(Valeurs!$B40/Valeurs!F40-1,"") -> 0.092079678 | F40: =IFERROR(Valeurs!$B40/Valeurs!G40-1,"") -> 0.11641032 | G40: =IFERROR(Valeurs!$B40/Valeurs!H40-1,"") -> 0.17915644 | H40: =IFERROR(Valeurs!$B40/Valeurs!I40-1,"") -> 0.18415872 | I40: =IFERROR(Valeurs!$B40/Valeurs!J40-1,"") -> 0.23798078 | ... M40: =IFERROR(Valeurs!$B40/Valeurs!N40-1,"") -> 0.23558025
A41: MXWO INDEX | B41: =IFERROR(Valeurs!$B41/Valeurs!C41-1,"") -> 0.028358868 | C41: =IFERROR(Valeurs!$B41/Valeurs!D41-1,"") -> 0.038940021 | D41: =IFERROR(Valeurs!$B41/Valeurs!E41-1,"") -> 0.099548628 | E41: =IFERROR(Valeurs!$B41/Valeurs!F41-1,"") -> 0.072764739 | F41: =IFERROR(Valeurs!$B41/Valeurs!G41-1,"") -> 0.098206458 | G41: =IFERROR(Valeurs!$B41/Valeurs!H41-1,"") -> 0.15616387 | H41: =IFERROR(Valeurs!$B41/Valeurs!I41-1,"") -> 0.1540558 | I41: =IFERROR(Valeurs!$B41/Valeurs!J41-1,"") -> 0.20854619 | ... M41: =IFERROR(Valeurs!$B41/Valeurs!N41-1,"") -> 0.19384108
A42: CCMP Index | B42: =IFERROR(Valeurs!$B42/Valeurs!C42-1,"") -> 0.0097999421 | C42: =IFERROR(Valeurs!$B42/Valeurs!D42-1,"") -> 0.070493954 | D42: =IFERROR(Valeurs!$B42/Valeurs!E42-1,"") -> 0.10430483 | E42: =IFERROR(Valeurs!$B42/Valeurs!F42-1,"") -> 0.11826456 | F42: =IFERROR(Valeurs!$B42/Valeurs!G42-1,"") -> 0.13226587 | G42: =IFERROR(Valeurs!$B42/Valeurs!H42-1,"") -> 0.19298179 | H42: =IFERROR(Valeurs!$B42/Valeurs!I42-1,"") -> 0.20577335 | I42: =IFERROR(Valeurs!$B42/Valeurs!J42-1,"") -> 0.26453968 | ... M42: =IFERROR(Valeurs!$B42/Valeurs!N42-1,"") -> 0.26559513
A43: FED FUNDS | B43: =IFERROR(Valeurs!$B43-Valeurs!C43,"") -> 0 | C43: =IFERROR(Valeurs!$B43-Valeurs!D43,"") -> 0 | D43: =IFERROR(Valeurs!$B43-Valeurs!E43,"") -> 0 | E43: =IFERROR(Valeurs!$B43-Valeurs!F43,"") -> 0 | F43: =IFERROR(Valeurs!$B43-Valeurs!G43,"") -> 0 | G43: =IFERROR(Valeurs!$B43-Valeurs!H43,"") -> 0 | H43: =IFERROR(Valeurs!$B43-Valeurs!I43,"") -> 0 | I43: =IFERROR(Valeurs!$B43-Valeurs!J43,"") -> 0 | ... M43: =IFERROR(Valeurs!$B43-Valeurs!N43,"") -> 0.25
A44: XAU Curncy | B44: =IFERROR(Valeurs!$B44/Valeurs!C44-1,"") -> 0.0062436938 | C44: =IFERROR(Valeurs!$B44/Valeurs!D44-1,"") -> -0.033785742 | D44: =IFERROR(Valeurs!$B44/Valeurs!E44-1,"") -> -0.011605154 | E44: =IFERROR(Valeurs!$B44/Valeurs!F44-1,"") -> 0.08243425 | F44: =IFERROR(Valeurs!$B44/Valeurs!G44-1,"") -> 0.15893504 | G44: =IFERROR(Valeurs!$B44/Valeurs!H44-1,"") -> 0.16317508 | H44: =IFERROR(Valeurs!$B44/Valeurs!I44-1,"") -> 0.15547479 | I44: =IFERROR(Valeurs!$B44/Valeurs!J44-1,"") -> 0.17810806 | ... M44: =IFERROR(Valeurs!$B44/Valeurs!N44-1,"") -> 0.1936431
A45: CL1 Comdty | B45: =IFERROR(Valeurs!$B45/Valeurs!C45-1,"") -> 0.0013693514 | C45: =IFERROR(Valeurs!$B45/Valeurs!D45-1,"") -> 0.0047464402 | D45: =IFERROR(Valeurs!$B45/Valeurs!E45-1,"") -> -0.027210062 | E45: =IFERROR(Valeurs!$B45/Valeurs!F45-1,"") -> -0.0074037512 | F45: =IFERROR(Valeurs!$B45/Valeurs!G45-1,"") -> 0.015784821 | G45: =IFERROR(Valeurs!$B45/Valeurs!H45-1,"") -> 0.10859978 | H45: =IFERROR(Valeurs!$B45/Valeurs!I45-1,"") -> 0.12613748 | I45: =IFERROR(Valeurs!$B45/Valeurs!J45-1,"") -> 0.059955198 | ... M45: =IFERROR(Valeurs!$B45/Valeurs!N45-1,"") -> 0.084828051
...

Sheet Données
A1: GDP CQOQ Index — Date | B1: GDP CQOQ Index — Valeur | C1: GDP CYOY Index — Date | D1: GDP CYOY Index — Valeur | E1: GDP CURY Index — Date | F1: GDP CURY Index — Valeur | G1: GDP PIQQ Index — Date | H1: GDP PIQQ Index — Valeur | I1: USURTOT Index — Date | J1: USURTOT Index — Valeur | K1: NFP TCH Index — Date | L1: NFP TCH Index — Valeur | M1: ADP CHNG Index — Date | N1: ADP CHNG Index — Valeur | O1: LEI WKIJ Index — Date | P1: LEI WKIJ Index — Valeur | Q1: USHEYOY Index — Date | R1: USHEYOY Index — Valeur | S1: CPI XYOY Index — Date | T1: CPI XYOY Index — Valeur | U1: PCE CYOY Index — Date | V1: PCE CYOY Index — Valeur | W1: PPI XYOY Index — Date | X1: PPI XYOY Index — Valeur | Y1: IP YOY Index — Date | Z1: IP YOY Index — Valeur | AA1: CPTICHNG Index — Date | AB1: CPTICHNG Index — Valeur | AC1: DGNOYOY Index — Date | AD1: DGNOYOY Index — Valeur | AE1: MPMIUSCA Index — Date | AF1: MPMIUSCA Index — Valeur | AG1: NAPMPMI Index — Date | AH1: NAPMPMI Index — Valeur | AI1: MPMIUSMA Index — Date | AJ1: MPMIUSMA Index — Valeur | AK1: MPMIUSSA Index — Date | AL1: MPMIUSSA Index — Valeur | AM1: NAPMNMI Index — Date | AN1: NAPMNMI Index — Valeur | AO1: CFNAI Index — Date | AP1: CFNAI Index — Valeur | AQ1: OUTFGAF Index — Date | AR1: OUTFGAF Index — Valeur | AS1: EMPRGBCI Index — Date | AT1: EMPRGBCI Index — Valeur | AU1: RCHSINDX Index — Date | AV1: RCHSINDX Index — Valeur | AW1: CHPMINDX Index — Date | AX1: CHPMINDX Index — Valeur | AY1: LEI YOY Index — Date | AZ1: LEI YOY Index — Valeur | BA1: NHSPATOT Index — Date | BB1: NHSPATOT Index — Valeur | BC1: ETSLTOTL Index — Date | BD1: ETSLTOTL Index — Valeur | BE1: RSTAXMOM Index — Date | BF1: RSTAXMOM Index — Valeur | BG1: RSTAXYOY Index — Date | BH1: RSTAXYOY Index — Valeur | BI1: SAARTOTL Index — Date | BJ1: SAARTOTL Index — Valeur | BK1: PITLYOY Index — Date | BL1: PITLYOY Index — Valeur | BM1: PCE CHY% Index — Date | BN1: PCE CHY% Index — Valeur | BO1: PCE CHNC Index — Date | BP1: PCE CHNC Index — Valeur | BQ1: CONCCONF Index — Date | BR1: CONCCONF Index — Valeur | BS1: CONSSENT Index — Date | BT1: CONSSENT Index — Valeur | BU1: SPX INDEX — Date | BV1: SPX INDEX — Valeur | BW1: MXWO INDEX — Date | BX1: MXWO INDEX — Valeur | BY1: CCMP Index — Date | BZ1: CCMP Index — Valeur | CA1: FED FUNDS — Date | CB1: FED FUNDS — Valeur | CC1: XAU Curncy — Date | CD1: XAU Curncy — Valeur | CE1: CL1 Comdty — Date | CF1: CL1 Comdty — Valeur | CG1: ISIX62IU Index — Date | CH1: ISIX62IU Index — Valeur | CI1: LMCADS03 Comdty — Date | CJ1: LMCADS03 Comdty — Valeur | CK1: RTY Index — Date | CL1: RTY Index — Valeur | CM1: BITCOIN Index — Date | CN1: BITCOIN Index — Valeur | CO1: ETHEREUM Index — Date | CP1: ETHEREUM Index — Valeur | CQ1: S5FINL Index (R1) — Date | CR1: S5FINL Index (R1) — Valeur | CS1: S5INFT Index (R2) — Date | CT1: S5INFT Index (R2) — Valeur | CU1: S5HLTH Index (L1) — Date | CV1: S5HLTH Index (L1) — Valeur | CW1: S5COND Index (L1) — Date | CX1: S5COND Index (L1) — Valeur | CY1: S5TELS Index (R1) — Date | CZ1: S5TELS Index (R1) — Valeur | DA1: S5INDU Index (L1) — Date | DB1: S5INDU Index (L1) — Valeur | DC1: S5CONS Index (L1) — Date | DD1: S5CONS Index (L1) — Valeur | DE1: S5ENRS Index (L1) — Date | DF1: S5ENRS Index (L1) — Valeur | DG1: S5UTIL Index (R1) — Date | DH1: S5UTIL Index (R1) — Valeur | DI1: S5MATR Index (R1) — Date | DJ1: S5MATR Index (R1) — Valeur | DK1: S5RLST Index (R1) — Date | DL1: S5RLST Index (R1) — Valeur
A2: 25658 | B2: -0.6 | C2: 25658 | D2: 0.3 | E2: 25658 | F2: 5.8 | G2: 25658 | H2: 5.6 | I2: 25599 | J2: 3.9 | K2: 25599 | L2: -65 | M2: 40237 | N2: -45 | O2: 25599 | P2: 251.3 | Q2: 25599 | R2: 6.1 | S2: 25599 | T2: 6.2 | U2: 25599 | V2: 4.70005 | W2: 27060 | X2: 5.5 | Y2: 25599 | Z2: -0.68 | AA2: 25599 | AB2: 83.6586 | AC2: 33663 | AD2: -3.2 | AE2: 44377 | AF2: 63.7 | AG2: 25599 | AH2: 48.7 | AI2: 44377 | AJ2: 62.1 | AK2: 44377 | AL2: 64.6 | AM2: 35642 | AN2: 56.7 | AO2: 25599 | AP2: -1.33 | AQ2: 25599 | AR2: -13.1 | AS2: 37103 | AT2: -13.3 | AU2: 34303 | AV2: 8 | AW2: 25599 | AX2: 45.2 | AY2: 25599 | AZ2: -3.2 | BA2: 25599 | BB2: 1062 | BC2: 36191 | BD2: 5.23 | BE2: 33663 | BF2: -0.2 | BG2: 34000 | BH2: 5.3 | BI2: 27790 | BJ2: 12.5 | BK2: 25599 | BL2: 9.1 | BM2: 36556 | BN2: 5.4 | BO2: 32932 | BP2: -0.5 | BQ2: 25627 | BR2: 101.7 | BS2: 28521 | BT2: 83.7 | BU2: 25570 | BV2: 93 | BW2: 25575 | BX2: 100.67 | BY2: 25969 | BZ2: 100 | CA2: 19997 | CB2: 1.07 | CC2: 25658 | CD2: 35.09 | CE2: 30405 | CF2: 29.4 | CG2: 40899 | CH2: 135.6 | CI2: 31503 | CJ2: 1466.8 | CK2: 28853 | CL2: 40.237 | CM2: 40378 | CN2: 0.1 | CO2: 42738 | CP2: 10 | CQ2: 32780 | CR2: 82.76 | CS2: 32780 | CT2: 70.58 | CU2: 32780 | CV2: 68.33 | CW2: 32780 | CX2: 75.8588 | CY2: 32780 | CZ2: 92.56 | DA2: 32780 | DB2: 75.36 | DC2: 32780 | DD2: 58.93 | DE2: 32780 | DF2: 82.42 | DG2: 32780 | DH2: 95.71 | DI2: 32780 | DJ2: 78.8 | DK2: 37256 | DL2: 97.15
A3: 25749 | B3: 0.6 | C3: 25749 | D3: 0.2 | E3: 25749 | F3: 5.8 | G3: 25749 | H3: 5.9 | I3: 25627 | J3: 4.2 | K3: 25627 | L3: 129 | M3: 40268 | N3: 5 | O3: 25627 | P3: 258.5 | Q3: 25627 | R3: 6.1 | S3: 25627 | T3: 6.1 | U3: 25627 | V3: 4.74111 | W3: 27088 | X3: 5.7 | Y3: 25627 | Z3: -1.37 | AA3: 25627 | AB3: 83.3422 | AC3: 33694 | AD3: 6.8 | AE3: 44408 | AF3: 59.9 | AG3: 25627 | AH3: 47.4 | AI3: 44408 | AJ3: 63.4 | AK3: 44408 | AL3: 59.9 | AM3: 35673 | AN3: 62 | AO3: 25627 | AP3: -0.15 | AQ3: 25627 | AR3: -18.1 | AS3: 37134 | AT3: -8 | AU3: 34334 | AV3: 12 | AW3: 25627 | AX3: 43 | AY3: 25627 | AZ3: -4.3 | BA3: 25627 | BB3: 1118 | BC3: 36219 | BD3: 5.1 | BE3: 33694 | BF3: 0 | BG3: 34028 | BH3: 5.1 | BI3: 27819 | BJ3: 13 | BK3: 25627 | BL3: 9.1 | BM3: 36585 | BN3: 5.8 | BO3: 32963 | BP3: 0.3 | BQ3: 25688 | BR3: 98 | BS3: 28549 | BT3: 84.3 | BU3: 25573 | BV3: 93.46 | BW3: 25582 | BX3: 99.77 | BY3: 25976 | BZ3: 102.05 | CA3: 20089 | CB3: 1.28 | CC3: 25688 | CD3: 35.62 | CE3: 30406 | CF3: 29.29 | CG3: 40900 | CH3: 135.8 | CI3: 31504 | CJ3: 1453.3 | CK3: 28857 | CL3: 40.523 | CM3: 40379 | CN3: 0.09 | CO3: 42739 | CP3: 11.13 | CQ3: 32871 | CR3: 76.14 | CS3: 32871 | CT3: 64.7 | CU3: 32871 | CV3: 72.56 | CW3: 32871 | CX3: 71.2032 | CY3: 32871 | CZ3: 99.89 | DA3: 32871 | DB3: 75.11 | DC3: 32871 | DD3: 62.33 | DE3: 32871 | DF3: 91.62 | DG3: 32871 | DH3: 103.76 | DI3: 32871 | DJ3: 78.08 | DK3: 37344 | DL3: 96.29
A4: 25841 | B4: 3.7 | C4: 25841 | D4: 0.4 | E4: 25841 | F4: 5.4 | G4: 25841 | H4: 3.3 | I4: 25658 | J4: 4.4 | K4: 25658 | L4: 146 | M4: 40298 | N4: 287 | O4: 25658 | P4: 268.3 | Q4: 25658 | R4: 6.3 | S4: 25658 | T4: 6.1 | U4: 25658 | V4: 4.64141 | W4: 27119 | X4: 6.5 | Y4: 25658 | Z4: -2.27 | AA4: 25658 | AB4: 82.9743 | AC4: 33724 | AD4: 7.6 | AE4: 44439 | AF4: 55.4 | AG4: 25658 | AH4: 46.9 | AI4: 44439 | AJ4: 61.1 | AK4: 44439 | AL4: 55.1 | AM4: 35703 | AN4: 56.2 | AO4: 25658 | AP4: -0.57 | AQ4: 25658 | AR4: -31.2 | AS4: 37164 | AT4: -12.5 | AU4: 34365 | AV4: 16 | AW4: 25658 | AX4: 41.4 | AY4: 25658 | AZ4: -5 | BA4: 25658 | BB4: 1132 | BC4: 36250 | BD4: 5.15 | BE4: 33724 | BF4: 0.4 | BG4: 34059 | BH4: 4.6 | BI4: 27850 | BJ4: 13.1 | BK4: 25658 | BL4: 8.7 | BM4: 36616 | BN4: 6 | BO4: 32993 | BP4: 0.2 | BQ4: 25749 | BR4: 88.1 | BS4: 28580 | BT4: 78.8 | BU4: 25574 | BV4: 92.82 | BW4: 25589 | BX4: 98.38 | BY4: 25983 | BZ4: 100.7 | CA4: 20179 | CB4: 1.35 | CC4: 25717 | CD4: 35.95 | CE4: 30410 | CF4: 29.44 | CG4: 40903 | CH4: 136.2 | CI4: 31505 | CJ4: 1435 | CK4: 28858 | CL4: 41.247 | CM4: 40380 | CN4: 0.1 | CO4: 42740 | CP4: 10.6 | CQ4: 32962 | CR4: 68.03 | CS4: 32962 | CT4: 70.06 | CU4: 32962 | CV4: 68.07 | CW4: 32962 | CX4: 69.6771 | CY4: 32962 | CZ4: 90.85 | DA4: 32962 | DB4: 76.11 | DC4: 32962 | DD4: 58.61 | DE4: 32962 | DF4: 90.07 | DG4: 32962 | DH4: 95.7 | DI4: 32962 | DJ4: 73.57 | DK4: 37435 | DL4: 97.62
A5: 25933 | B5: -4.2 | C5: 25933 | D5: -0.2 | E5: 25933 | F5: 4.9 | G5: 25933 | H5: 5.3 | I5: 25688 | J5: 4.6 | K5: 25688 | L5: -103 | M5: 40329 | N5: 95 | O5: 25688 | P5: 340.5 | Q5: 25688 | R5: 6 | S5: 25688 | T5: 5.8 | U5: 25688 | V5: 4.65464 | W5: 27149 | X5: 7.1 | Y5: 25688 | Z5: -2.16 | AA5: 25688 | AB5: 82.5037 | AC5: 33755 | AD5: 5.4 | AE5: 44469 | AF5: 55 | AG5: 25688 | AH5: 45 | AI5: 44469 | AJ5: 60.7 | AK5: 44469 | AL5: 54.9 | AM5: 35734 | AN5: 56.6 | AO5: 25688 | AP5: -0.69 | AQ5: 25688 | AR5: -16.9 | AS5: 37195 | AT5: -14.7 | AU5: 34393 | AV5: 5 | AW5: 25688 | AX5: 38.9 | AY5: 25688 | AZ5: -6.5 | BA5: 25688 | BB5: 1224 | BC5: 36280 | BD5: 5.08 | BE5: 33755 | BF5: 0.2 | BG5: 34089 | BH5: 5.6 | BI5: 27880 | BJ5: 12.9 | BK5: 25688 | BL5: 9.6 | BM5: 36646 | BN5: 5.2 | BO5: 33024 | BP5: -0.1 | BQ5: 25811 | BR5: 91 | BS5: 28610 | BT5: 81.6 | BU5: 25575 | BV5: 92.63 | BW5: 25596 | BX5: 95.91 | BY5: 25990 | BZ5: 101.34 | CA5: 20270 | CB5: 1.64 | CC5: 25749 | CD5: 35.44 | CE5: 30411 | CF5: 29.71 | CG5: 40904 | CH5: 136.3 | CI5: 31506 | CJ5: 1432 | CK5: 28859 | CL5: 41.863 | CM5: 40381 | CN5: 0.06 | CO5: 42741 | CP5: 10.71 | CQ5: 33053 | CR5: 70.42 | CS5: 33053 | CT5: 76.6 | CU5: 33053 | CV5: 80.36 | CW5: 33053 | CX5: 73.775 | CY5: 33053 | CZ5: 89.1 | DA5: 33053 | DB5: 79.49 | DC5: 33053 | DD5: 67.71 | DE5: 33053 | DF5: 89.83 | DG5: 33053 | DH5: 94.69 | DI5: 33053 | DJ5: 72.67 | DK5: 37529 | DL5: 83.37
A6: 26023 | B6: 11.3 | C6: 26023 | D6: 2.7 | E6: 26023 | F6: 8 | G6: 26023 | H6: 6.2 | I6: 25719 | J6: 4.8 | K6: 25719 | L6: -224 | M6: 40359 | N6: 22 | O6: 25719 | P6: 304.5 | Q6: 25719 | R6: 6 | S6: 25719 | T6: 6 | U6: 25719 | V6: 4.60519 | W6: 27180 | X6: 8.8 | Y6: 25719 | Z6: -1.9 | AA6: 25719 | AB6: 82.152 | AC6: 33785 | AD6: 6.6 | AE6: 44500 | AF6: 57.6 | AG6: 25719 | AH6: 47.2 | AI6: 44500 | AJ6: 58.4 | AK6: 44500 | AL6: 58.7 | AM6: 35764 | AN6: 58.5 | AO6: 25719 | AP6: -0.32 | AQ6: 25719 | AR6: -21.5 | AS6: 37225 | AT6: -21.5 | AU6: 34424 | AV6: 19 | AW6: 25719 | AX6: 34.9 | AY6: 25719 | AZ6: -5.9 | BA6: 25719 | BB6: 1328 | BC6: 36311 | BD6: 5.19 | BE6: 33785 | BF6: 0 | BG6: 34120 | BH6: 6.2 | BI6: 27911 | BJ6: 12.6 | BK6: 25719 | BL6: 8.5 | BM6: 36677 | BN6: 5.3 | BO6: 33054 | BP6: 0.3 | BQ6: 25872 | BR6: 83.2 | BS6: 28641 | BT6: 82.9 | BU6: 25576 | BV6: 92.68 | BW6: 25598 | BX6: 94.25 | BY6: 25997 | BZ6: 103 | CA6: 20362 | CB6: 2.18 | CC6: 25780 | CD6: 35.32 | CE6: 30412 | CF6: 29.9 | CG6: 40905 | CH6: 136.5 | CI6: 31509 | CJ6: 1438.5 | CK6: 28860 | CL6: 42.422 | CM6: 40382 | CN6: 0.08 | CO6: 42744 | CP6: 10.88 | CQ6: 33144 | CR6: 51.02 | CS6: 33144 | CT6: 59.43 | CU6: 33144 | CV6: 73.37 | CW6: 33144 | CX6: 55.6584 | CY6: 33144 | CZ6: 79.98 | DA6: 33144 | DB6: 62.76 | DC6: 33144 | DD6: 60.95 | DE6: 33144 | DF6: 93.06 | DG6: 33144 | DH6: 88.08 | DI6: 33144 | DJ6: 61.51 | DK6: 37621 | DL6: 82.48
A7: 26114 | B7: 2.2 | C7: 26114 | D7: 3.1 | E7: 26114 | F7: 8.3 | G7: 26114 | H7: 5.5 | I7: 25749 | J7: 4.9 | K7: 25749 | L7: -95 | M7: 40390 | N7: 279 | O7: 25749 | P7: 296.5 | Q7: 25749 | R7: 5.9 | S7: 25749 | T7: 6.5 | U7: 25749 | V7: 4.62011 | W7: 27210 | X7: 10.4 | Y7: 25749 | Z7: -3.16 | AA7: 25749 | AB7: 81.6333 | AC7: 33816 | AD7: -6.9 | AE7: 44530 | AF7: 57.2 | AG7: 25749 | AH7: 51.1 | AI7: 44530 | AJ7: 58.3 | AK7: 44530 | AL7: 58 | AM7: 35795 | AN7: 55.5 | AO7: 25749 | AP7: -0.27 | AQ7: 25749 | AR7: -8.4 | AS7: 37256 | AT7: -9.8 | AU7: 34454 | AV7: 16 | AW7: 25749 | AX7: 43.3 | AY7: 25749 | AZ7: -5.4 | BA7: 25749 | BB7: 1322 | BC7: 36341 | BD7: 5.43 | BE7: 33816 | BF7: 0.6 | BG7: 34150 | BH7: 6.1 | BI7: 27941 | BJ7: 12.7 | BK7: 25749 | BL7: 8.2 | BM7: 36707 | BN7: 5 | BO7: 33085 | BP7: 0.2 | BQ7: 25933 | BR7: 75.7 | BS7: 28671 | BT7: 80 | BU7: 25577 | BV7: 92.4 | BW7: 25603 | BX7: 95.91 | BY7: 26004 | BZ7: 104.5 | CA7: 20453 | CB7: 2.48 | CC7: 25811 | CD7: 35.38 | CE7: 30413 | CF7: 30.17 | CG7: 40906 | CH7: 137.5 | CI7: 31510 | CJ7: 1450.8 | CK7: 28863 | CL7: 42.306 | CM7: 40385 | CN7: 0.08 | CO7: 42745 | CP7: 10.88 | CQ7: 33238 | CR7: 57.56 | CS7: 33238 | CT7: 65.01 | CU7: 33238 | CV7: 82.82 | CW7: 33238 | CX7: 60.5674 | CY7: 33238 | CZ7: 82.24 | DA7: 33238 | DB7: 67.38 | DC7: 33238 | DD7: 70.06 | DE7: 33238 | DF7: 90.34 | DG7: 33238 | DH7: 96.17 | DI7: 33238 | DJ7: 67.2 | DK7: 37711 | DL7: 82.25
A8: 26206 | B8: 3.3 | C8: 26206 | D8: 3 | E8: 26206 | F8: 8.4 | G8: 26206 | H8: 4.1 | I8: 25780 | J8: 5 | K8: 25780 | L8: 24 | M8: 40421 | N8: 83 | O8: 25780 | P8: 282.5 | Q8: 25780 | R8: 5.9 | S8: 25780 | T8: 6.2 | U8: 25780 | V8: 4.53249 | W8: 27241 | X8: 12.1 | Y8: 25780 | Z8: -3.44 | AA8: 25780 | AB8: 81.5815 | AC8: 33847 | AD8: -3.4 | AE8: 44561 | AF8: 57 | AG8: 25780 | AH8: 49.5 | AI8: 44561 | AJ8: 57.7 | AK8: 44561 | AL8: 57.6 | AM8: 35826 | AN8: 57 | AO8: 25780 | AP8: -0.01 | AQ8: 25780 | AR8: 7 | AS8: 37287 | AT8: 1.4 | AU8: 34485 | AV8: 18 | AW8: 25780 | AX8: 46.1 | AY8: 25780 | AZ8: -4.8 | BA8: 25780 | BB8: 1324 | BC8: 36372 | BD8: 5.25 | BE8: 33847 | BF8: 0.9 | BG8: 34181 | BH8: 6.4 | BI8: 27972 | BJ8: 13.1 | BK8: 25780 | BL8: 8.2 | BM8: 36738 | BN8: 4.9 | BO8: 33116 | BP8: 0 | BQ8: 25992 | BR8: 77.4 | BS8: 28702 | BT8: 82.4 | BU8: 25580 | BV8: 91.7 | BW8: 25610 | BX8: 95.47 | BY8: 26011 | BZ8: 105.77 | CA8: 20544 | CB8: 2.5 | CC8: 25841 | CD8: 36.19 | CE8: 30414 | CF8: 30.38 | CG8: 40907 | CH8: 138.2 | CI8: 31511 | CJ8: 1441.7 | CK8: 28864 | CL8: 42.668 | CM8: 40386 | CN8: 0.08 | CO8: 42746 | CP8: 10.15 | CQ8: 33326 | CR8: 72 | CS8: 33326 | CT8: 74.17 | CU8: 33326 | CV8: 98.02 | CW8: 33326 | CX8: 73.4017 | CY8: 33326 | CZ8: 84.53 | DA8: 33326 | DB8: 77.53 | DC8: 33326 | DD8: 82.1 | DE8: 33326 | DF8: 95.4 | DG8: 33326 | DH8: 98.89 | DI8: 33326 | DJ8: 73.08 | DK8: 37802 | DL8: 88.53
A9: 26298 | B9: 0.9 | C9: 26298 | D9: 4.4 | E9: 26298 | F9: 9.3 | G9: 26298 | H9: 3.4 | I9: 25811 | J9: 5.1 | K9: 25811 | L9: -116 | M9: 40451 | N9: 136 | O9: 25811 | P9: 291.5 | Q9: 25811 | R9: 5.9 | S9: 25811 | T9: 6.2 | U9: 25811 | V9: 4.60109 | W9: 27272 | X9: 13.7 | Y9: 25811 | Z9: -3.83 | AA9: 25811 | AB9: 81.1858 | AC9: 33877 | AD9: -0.5 | AE9: 44592 | AF9: 51.1 | AG9: 25811 | AH9: 47.3 | AI9: 44592 | AJ9: 55.5 | AK9: 44592 | AL9: 51.2 | AM9: 35854 | AN9: 56.2 | AO9: 25811 | AP9: -0.56 | AQ9: 25811 | AR9: 6.9 | AS9: 37315 | AT9: 13.3 | AU9: 34515 | AV9: 20 | AW9: 25811 | AX9: 45.8 | AY9: 25811 | AZ9: -4.3 | BA9: 25811 | BB9: 1394 | BC9: 36403 | BD9: 5.23 | BE9: 33877 | BF9: 0.2 | BG9: 34212 | BH9: 5.2 | BI9: 28003 | BJ9: 12.6 | BK9: 25811 | BL9: 7.7 | BM9: 36769 | BN9: 4.9 | BO9: 33146 | BP9: 0 | BQ9: 26053 | BR9: 75.2 | BS9: 28733 | BT9: 78.4 | BU9: 25581 | BV9: 91.79 | BW9: 25617 | BX9: 95.63 | BY9: 26018 | BZ9: 105.07 | CA9: 20635 | CB9: 2.71 | CC9: 25871 | CD9: 37.52 | CE9: 30417 | CF9: 30.26 | CG9: 40914 | CH9: 140.6 | CI9: 31512 | CJ9: 1445.4 | CK9: 28865 | CL9: 42.575 | CM9: 40387 | CN9: 0.08 | CO9: 42747 | CP9: 10.66 | CQ9: 33417 | CR9: 70.63 | CS9: 33417 | CT9: 67.54 | CU9: 33417 | CV9: 96.91 | CW9: 33417 | CX9: 75.4513 | CY9: 33417 | CZ9: 82.78 | DA9: 33417 | DB9: 79.4 | DC9: 33417 | DD9: 78.32 | DE9: 33417 | DF9: 91.54 | DG9: 33417 | DH9: 94.37 | DI9: 33417 | DJ9: 79.93 | DK9: 37894 | DL9: 95.39
A10: 26389 | B10: 7.6 | C10: 26389 | D10: 3.5 | E10: 26389 | F10: 8.4 | G10: 26389 | H10: 6.6 | I10: 25841 | J10: 5.4 | K10: 25841 | L10: 7 | M10: 40482 | N10: 39 | O10: 25841 | P10: 325 | Q10: 25841 | R10: 5.8 | S10: 25841 | T10: 6.2 | U10: 25841 | V10: 4.61811 | W10: 27302 | X10: 15.1 | Y10: 25841 | Z10: -4.47 | AA10: 25841 | AB10: 80.3792 | AC10: 33908 | AD10: 4.2 | AE10: 44620 | AF10: 55.9 | AG10: 25841 | AH10: 44.1 | AI10: 44620 | AJ10: 57.3 | AK10: 44620 | AL10: 56.5 | AM10: 35885 | AN10: 54.7 | AO10: 25841 | AP10: -0.63 | AQ10: 25841 | AR10: 14 | AS10: 37346 | AT10: 13.8 | AU10: 34546 | AV10: 18 | AW10: 25841 | AX10: 41.2 | AY10: 25841 | AZ10: -4.6 | BA10: 25841 | BB10: 1426 | BC10: 36433 | BD10: 5.12 | BE10: 33908 | BF10: 0.9 | BG10: 34242 | BH10: 6 | BI10: 28033 | BJ10: 13.2 | BK10: 25841 | BL10: 7.4 | BM10: 36799 | BN10: 5.2 | BO10: 33177 | BP10: -0.6 | BQ10: 26114 | BR10: 82.3 | BS10: 28763 | BT10: 80.4 | BU10: 25582 | BV10: 91.65 | BW10: 25624 | BX10: 96.87 | BY10: 26025 | BZ10: 106.86 | CA10: 20726 | CB10: 2.95 | CC10: 25902 | CD10: 37.44 | CE10: 30418 | CF10: 30.83 | CG10: 40917 | CH10: 141.2 | CI10: 31513 | CJ10: 1454.2 | CK10: 28866 | CL10: 42.764 | CM10: 40388 | CN10: 0.09 | CO10: 42748 | CP10: 10.22 | CQ10: 33511 | CR10: 76.9 | CS10: 33511 | CT10: 68.71 | CU10: 33511 | CV10: 105.5 | CW10: 33511 | CX10: 78.4398 | CY10: 33511 | CZ10: 83.58 | DA10: 33511 | DB10: 79.09 | DC10: 33511 | DD10: 84.31 | DE10: 33511 | DF10: 95.7 | DG10: 33511 | DH10: 104.08 | DI10: 33511 | DJ10: 79.4 | DK10: 37986 | DL10: 99.63
A11: 26480 | B11: 9.4 | C11: 26480 | D11: 5.2 | E11: 26480 | F11: 9.5 | G11: 26480 | H11: 2.5 | I11: 25872 | J11: 5.5 | K11: 25872 | L11: -423 | M11: 40512 | N11: 240 | O11: 25872 | P11: 329.5 | Q11: 25872 | R11: 5.5 | S11: 25872 | T11: 6.4 | U11: 25872 | V11: 4.68396 | W11: 27333 | X11: 16.9 | Y11: 25872 | Z11: -6.41 | AA11: 25872 | AB11: 78.5307 | AC11: 33938 | AD11: -1.4 | AE11: 44651 | AF11: 57.7 | AG11: 25872 | AH11: 42.4 | AI11: 44651 | AJ11: 58.8 | AK11: 44651 | AL11: 58 | AM11: 35915 | AN11: 54.9 | AO11: 25872 | AP11: -1.76 | AQ11: 25872 | AR11: 3.7 | AS11: 37376 | AT11: 20.2 | AU11: 34577 | AV11: 22 | AW11: 25872 | AX11: 35.7 | AY11: 25872 | AZ11: -3.9 | BA11: 25872 | BB11: 1564 | BC11: 36464 | BD11: 5.11 | BE11: 33938 | BF11: 0.3 | BG11: 34273 | BH11: 5.5 | BI11: 28064 | BJ11: 12.5 | BK11: 25872 | BL11: 7 | BM11: 36830 | BN11: 5 | BO11: 33207 | BP11: -0.1 | BQ11: 26176 | BR11: 82.1 | BS11: 28794 | BT11: 79.3 | BU11: 25583 | BV11: 91.68 | BW11: 25626 | BX11: 96.98 | BY11: 26032 | BZ11: 108.38 | CA11: 20820 | CB11: 2.94 | CC11: 25933 | CD11: 37.44 | CE11: 30419 | CF11: 30.82 | CG11: 40918 | CH11: 141.9 | CI11: 31516 | CJ11: 1454.5 | CK11: 28867 | CL11: 43.247 | CM11: 40389 | CN11: 0.08 | CO11: 42752 | CP11: 11.14 | CQ11: 33603 | CR11: 82.78 | CS11: 33603 | CT11: 69.3 | CU11: 33603 | CV11: 124.4 | CW11: 33603 | CX11: 83.7412 | CY11: 33603 | CZ11: 88.73 | DA11: 33603 | DB11: 84.89 | DC11: 33603 | DD11: 96.96 | DE11: 33603 | DF11: 92.5 | DG11: 33603 | DH11: 111.55 | DI11: 33603 | DJ11: 81.67 | DK11: 38077 | DL11: 107.11
A12: 26572 | B12: 3.8 | C12: 26572 | D12: 5.4 | E12: 26572 | F12: 9.6 | G12: 26572 | H12: 3.7 | I12: 25902 | J12: 5.9 | K12: 25902 | L12: -112 | M12: 40543 | N12: -96 | O12: 25902 | P12: 325.3 | Q12: 25902 | R12: 5.5 | S12: 25902 | T12: 6.6 | U12: 25902 | V12: 4.82164 | W12: 27363 | X12: 17.6 | Y12: 25902 | Z12: -6.09 | AA12: 25902 | AB12: 77.8174 | AC12: 33969 | AD12: 8.3 | AE12: 44681 | AF12: 56 | AG12: 25902 | AH12: 39.7 | AI12: 44681 | AJ12: 59.2 | AK12: 44681 | AL12: 55.6 | AM12: 35946 | AN12: 56.2 | AO12: 25902 | AP12: -1.02 | AQ12: 25902 | AR12: 6.4 | AS12: 37407 | AT12: 12.9 | AU12: 34607 | AV12: 21 | AW12: 25902 | AX12: 38.1 | AY12: 25902 | AZ12: -3.5 | BA12: 25902 | BB12: 1502 | BC12: 36494 | BD12: 5.09 | BE12: 33969 | BF12: 1.3 | BG12: 34303 | BH12: 5.6 | BI12: 28094 | BJ12: 13 | BK12: 25902 | BL12: 6.8 | BM12: 36860 | BN12: 4.6 | BO12: 33238 | BP12: -0.4 | BQ12: 26237 | BR12: 80.3 | BS12: 28824 | BT12: 75 | BU12: 25584 | BV12: 90.92 | BW12: 25631 | BX12: 96.98 | BY12: 26039 | BZ12: 109.96 | CA12: 20908 | CB12: 2.96 | CC12: 25962 | CD12: 37.87 | CE12: 30420 | CF12: 30.69 | CG12: 40919 | CH12: 142.5 | CI12: 31517 | CJ12: 1447.1 | CK12: 28870 | CL12: 43.497 | CM12: 40392 | CN12: 0.08 | CO12: 42753 | CP12: 10.56 | CQ12: 33694 | CR12: 82.55 | CS12: 33694 | CT12: 72.76 | CU12: 33694 | CV12: 107.93 | CW12: 33694 | CX12: 88.0847 | CY12: 33694 | CZ12: 81.93 | DA12: 33694 | DB12: 85.11 | DC12: 33694 | DD12: 92.65 | DE12: 33694 | DF12: 83.35 | DG12: 33694 | DH12: 101.53 | DI12: 33694 | DJ12: 85.45 | DK12: 38168 | DL12: 101.11
A13: 26664 | B13: 6.9 | C13: 26664 | D13: 6.9 | E13: 26664 | F13: 11.6 | G13: 26664 | H13: 4.6 | I13: 25933 | J13: 6.1 | K13: 25933 | L13: 383 | M13: 40574 | N13: 316 | O13: 25933 | P13: 304.8 | Q13: 25933 | R13: 6.1 | S13: 25933 | T13: 6.6 | U13: 25933 | V13: 4.95876 | W13: 27394 | X13: 17.7 | Y13: 25933 | Z13: -3.68 | AA13: 25933 | AB13: 79.3628 | AC13: 34000 | AD13: 0.4 | AE13: 44712 | AF13: 53.6 | AG13: 25933 | AH13: 45.4 | AI13: 44712 | AJ13: 57 | AK13: 44712 | AL13: 53.4 | AM13: 35976 | AN13: 55.1 | AO13: 25933 | AP13: 1.61 | AQ13: 25933 | AR13: 10.2 | AS13: 37437 | AT13: 8.9 | AU13: 34638 | AV13: 23 | AW13: 25933 | AX13: 37.3 | AY13: 25933 | AZ13: -1.6 | BA13: 25933 | BB13: 1767 | BC13: 36525 | BD13: 5.08 | BE13: 34000 | BF13: 0.5 | BG13: 34334 | BH13: 4.9 | BI13: 28125 | BJ13: 14.2 | BK13: 25933 | BL13: 6.9 | BM13: 36891 | BN13: 3.7 | BO13: 33269 | BP13: -0.8 | BQ13: 26298 | BR13: 85 | BS13: 28855 | BT13: 66.1 | BU13: 25587 | BV13: 89.65 | BW13: 25638 | BX13: 96.98 | BY13: 26046 | BZ13: 110.69 | CA13: 20999 | CB13: 3 | CC13: 25990 | CD13: 38.74 | CE13: 30421 | CF13: 30.48 | CG13: 40924 | CH13: 142.5 | CI13: 31518 | CJ13: 1461.1 | CK13: 28871 | CL13: 43.126 | CM13: 40393 | CN13: 0.08 | CO13: 42754 | CP13: 10.56 | CQ13: 33785 | CR13: 86.47 | CS13: 33785 | CT13: 71.16 | CU13: 33785 | CV13: 102.15 | CW13: 33785 | CX13: 88.0721 | CY13: 33785 | CZ13: 87.09 | DA13: 33785 | DB13: 83.21 | DC13: 33785 | DD13: 91.62 | DE13: 33785 | DF13: 91.56 | DG13: 33785 | DH13: 106.37 | DI13: 33785 | DJ13: 87.35 | DK13: 38260 | DL13: 105.73
... A37: 28855 | B37: 5.5 | C37: 28855 | D37: 6.7 | E37: 28855 | F37: 14.4 | G37: 28855 | H37: 8.1 | I37: 26664 | J37: 5.2 | K37: 26664 | L37: 295 | M37: 41305 | N37: 231 | O37: 26664 | P37: 246.5 | Q37: 26664 | R37: 7.5 | S37: 26664 | T37: 3 | U37: 26664 | V37: 3.05269 | W37: 28125 | X37: 5.7 | Y37: 26664 | Z37: 11.54 | AA37: 26664 | AB37: 87.4686 | AC37: 34730 | AD37: 9.2 | AE37: 45443 | AF37: 54.5 | AG37: 26664 | AH37: 70.5 | AI37: 45443 | AJ37: 51.3 | AK37: 45443 | AL37: 54.8 | AM37: 36707 | AN37: 56.9 | AO37: 26664 | AP37: 1.2 | AQ37: 26664 | AR37: 49.1 | AS37: 38168 | AT37: 27.1 | AU37: 35369 | AV37: 2 | AW37: 26664 | AX37: 73.6 | AY37: 26664 | AZ37: 11.2 | BA37: 26664 | BB37: 2419 | BC37: 37256 | BD37: 5.49 | BE37: 34730 | BF37: 0.4 | BG37: 35064 | BH37: 4.2 | BI37: 28855 | BJ37: 14.8 | BK37: 26664 | BL37: 12.3 | BM37: 37621 | BN37: 2.9 | BO37: 34000 | BP37: -0.2 | BQ37: 27759 | BR37: 93.7 | BS37: 29586 | BT37: 64.5 | BU37: 25619 | BV37: 88.03 | BW37: 25778 | BX37: 84.08 | BY37: 26214 | BZ37: 110.74 | CA37: 23190 | CB37: 2.99 | CC37: 26723 | CD37: 74.2 | CE37: 30455 | CF37: 29.95 | CG37: 40983 | CH37: 144.8 | CI37: 31553 | CJ37: 1406.5 | CK37: 28906 | CL37: 43.955 | CM37: 40428 | CN37: 0.08 | CO37: 42789 | CP37: 13.81 | CQ37: 35976 | CR37: 330.52 | CS37: 35976 | CT37: 335.89 | CU37: 35976 | CV37: 325.2 | CW37: 35976 | CX37: 224.4729 | CY37: 35976 | CZ37: 206.18 | DA37: 35976 | DB37: 226.94 | DC37: 35976 | DD37: 243.22 | DE37: 35976 | DF37: 193.13 | DG37: 35976 | DH37: 155.08 | DI37: 35976 | DJ37: 150.27 | DK37: 40451 | DL37: 111.55
A38: 28945 | B38: 0.7 | C38: 28945 | D38: 6.5 | E38: 28945 | F38: 14.7 | G38: 28945 | H38: 7.7 | I38: 26695 | J38: 4.9 | K38: 26695 | L38: 349 | M38: 41333 | N38: 250 | O38: 26695 | P38: 228.5 | Q38: 26695 | R38: 6.1 | S38: 26695 | T38: 2.8 | U38: 26695 | V38: 2.67861 | W38: 28156 | X38: 5.7 | Y38: 26695 | Z38: 9.73 | AA38: 26695 | AB38: 87.8281 | AC38: 34758 | AD38: 12.6 | AG38: 26695 | AH38: 72.1 | AM38: 36738 | AN38: 55.3 | AO38: 26695 | AP38: 1.06 | AQ38: 26695 | AR38: 47.8 | AS38: 38199 | AT38: 35 | AU38: 35399 | AV38: 5 | AW38: 26695 | AX38: 77.8 | AY38: 26695 | AZ38: 10.9 | BA38: 26695 | BB38: 2271 | BC38: 37287 | BD38: 5.86 | BE38: 34758 | BF38: -1.2 | BG38: 35095 | BH38: 2.6 | BI38: 28886 | BJ38: 14.6 | BK38: 26695 | BL38: 11.2 | BM38: 37652 | BN38: 2.6 | BO38: 34028 | BP38: 0.2 | BQ38: 27819 | BR38: 101 | BS38: 29617 | BT38: 71.4 | BU38: 25623 | BV38: 87.99 | BW38: 25780 | BX38: 84.59 | BY38: 26221 | BZ38: 109.6 | CA38: 23284 | CB38: 3.48 | CC38: 26753 | CD38: 84.37 | CE38: 30456 | CF38: 30.3 | CG38: 40984 | CH38: 144.9 | CI38: 31554 | CJ38: 1406.1 | CK38: 28907 | CL38: 43.939 | CM38: 40429 | CN38: 0.08 | CO38: 42790 | CP38: 13.69 | CQ38: 36068 | CR38: 258.39 | CS38: 36068 | CT38: 331.83 | CU38: 36068 | CV38: 323.23 | CW38: 36068 | CX38: 186.952 | CY38: 36068 | CZ38: 215.5 | DA38: 36068 | DB38: 193.59 | DC38: 36068 | DD38: 204.86 | DE38: 36068 | DF38: 182.77 | DG38: 36068 | DH38: 160.89 | DI38: 36068 | DJ38: 126.67 | DK38: 40543 | DL38: 120.58
A39: 29036 | B39: 0.4 | C39: 29036 | D39: 2.7 | E39: 29036 | F39: 11.1 | G39: 29036 | H39: 10 | I39: 26723 | J39: 5 | K39: 26723 | L39: 397 | M39: 41364 | N39: 211 | O39: 26723 | P39: 221.3 | Q39: 26723 | R39: 5.8 | S39: 26723 | T39: 2.8 | U39: 26723 | V39: 2.72611 | W39: 28184 | X39: 5.6 | Y39: 26723 | Z39: 10.17 | AA39: 26723 | AB39: 88.8164 | AC39: 34789 | AD39: 12.4 | AG39: 26723 | AH39: 69.6 | AM39: 36769 | AN39: 57.6 | AO39: 26723 | AP39: 1.23 | AQ39: 26723 | AR39: 40.5 | AS39: 38230 | AT39: 15.2 | AU39: 35430 | AV39: 7 | AW39: 26723 | AX39: 77 | AY39: 26723 | AZ39: 9.9 | BA39: 26723 | BB39: 2226 | BC39: 37315 | BD39: 5.9 | BE39: 34789 | BF39: 0.7 | BG39: 35124 | BH39: 4.7 | BI39: 28914 | BJ39: 14.9 | BK39: 26723 | BL39: 10.9 | BM39: 37680 | BN39: 1.8 | BO39: 34059 | BP39: -0.6 | BQ39: 27880 | BR39: 89.5 | BS39: 29645 | BT39: 66.9 | BU39: 25624 | BV39: 89.35 | BW39: 25785 | BX39: 84.03 | BY39: 26228 | BZ39: 106.8 | CA39: 23376 | CB39: 3.38 | CC39: 26784 | CD39: 90.5 | CE39: 30459 | CF39: 30.27 | CG39: 40988 | CH39: 144.7 | CI39: 31555 | CJ39: 1398.6 | CK39: 28908 | CL39: 43.806 | CM39: 40430 | CN39: 0.08 | CO39: 42793 | CP39: 15.97 | CQ39: 36160 | CR39: 314.38 | CS39: 36160 | CT39: 452.51 | CU39: 36160 | CV39: 369.84 | CW39: 36160 | CX39: 241.2688 | CY39: 36160 | CZ39: 274.95 | DA39: 36160 | DB39: 227.93 | DC39: 36160 | DD39: 249.4 | DE39: 36160 | DF39: 183.44 | DG39: 36160 | DH39: 163.39 | DI39: 36160 | DJ39: 130.09 | DK39: 40633 | DL39: 131.23
A40: 29128 | B40: 3 | C40: 29128 | D40: 2.4 | E40: 29128 | F40: 11.4 | G40: 29128 | H40: 8.6 | I40: 26754 | J40: 4.9 | K40: 26754 | L40: 270 | M40: 41394 | N40: 144 | O40: 26754 | P40: 227.8 | Q40: 26754 | R40: 5.7 | S40: 26754 | T40: 3 | U40: 26754 | V40: 2.93917 | W40: 28215 | X40: 5.8 | Y40: 26754 | Z40: 9.44 | AA40: 26754 | AB40: 88.5532 | AC40: 34819 | AD40: 6.1 | AG40: 26754 | AH40: 69.6 | AM40: 36799 | AN40: 56.7 | AO40: 26754 | AP40: 0.45 | AQ40: 26754 | AR40: 58.5 | AS40: 38260 | AT40: 28.4 | AU40: 35461 | AV40: 2 | AW40: 26754 | AX40: 75 | AY40: 26754 | AZ40: 9 | BA40: 26754 | BB40: 2062 | BC40: 37346 | BD40: 5.63 | BE40: 34819 | BF40: 0.3 | BG40: 35155 | BH40: 5.2 | BI40: 28945 | BJ40: 14.8 | BK40: 26754 | BL40: 10.9 | BM40: 37711 | BN40: 2.4 | BO40: 34089 | BP40: 1.1 | BQ40: 27941 | BR40: 94.5 | BS40: 29676 | BT40: 66.5 | BU40: 25625 | BV40: 88.9 | BW40: 25792 | BX40: 82.52 | BY40: 26235 | BZ40: 105.1 | CA40: 23467 | CB40: 3.43 | CC40: 26815 | CD40: 101.96 | CE40: 30460 | CF40: 30.05 | CG40: 40989 | CH40: 144.7 | CI40: 31559 | CJ40: 1401 | CK40: 28909 | CL40: 43.601 | CM40: 40431 | CN40: 0.08 | CO40: 42794 | CP40: 16.9 | CQ40: 36250 | CR40: 336.32 | CS40: 36250 | CT40: 507.55 | CU40: 36250 | CV40: 379.77 | CW40: 36250 | CX40: 266.4461 | CY40: 36250 | CZ40: 283.23 | DA40: 36250 | DB40: 236.25 | DC40: 36250 | DD40: 228.15 | DE40: 36250 | DF40: 192.89 | DG40: 36250 | DH40: 146.39 | DI40: 36250 | DJ40: 131.07 | DK40: 40724 | DL40: 134.06
A41: 29220 | B41: 1 | C41: 29220 | D41: 1.3 | E41: 29220 | F41: 10 | G41: 29220 | H41: 7.5 | I41: 26784 | J41: 5 | K41: 26784 | L41: 171 | M41: 41425 | N41: 255 | O41: 26784 | P41: 239 | Q41: 26784 | R41: 5.7 | S41: 26784 | T41: 3.2 | U41: 26784 | V41: 3.29551 | W41: 28245 | X41: 5.9 | Y41: 26784 | Z41: 8.22 | AA41: 26784 | AB41: 88.1243 | AC41: 34850 | AD41: 8.1 | AG41: 26784 | AH41: 67.7 | AM41: 36830 | AN41: 56.7 | AO41: 26784 | AP41: 0.07 | AQ41: 26784 | AR41: 53.6 | AS41: 38291 | AT41: 24.5 | AU41: 35489 | AV41: -2 | AW41: 26784 | AX41: 74.5 | AY41: 26784 | AZ41: 7.9 | BA41: 26784 | BB41: 1908 | BC41: 37376 | BD41: 5.67 | BE41: 34850 | BF41: 0.8 | BG41: 35185 | BH41: 6 | BI41: 28975 | BJ41: 14.3 | BK41: 26784 | BL41: 11.6 | BM41: 37741 | BN41: 2.4 | BO41: 34120 | BP41: 0.1 | BQ41: 28003 | BR41: 94.6 | BS41: 29706 | BT41: 72.4 | BU41: 25626 | BV41: 89.5 | BW41: 25799 | BX41: 83.45 | BY41: 26242 | BZ41: 105.46 | CA41: 23558 | CB41: 3.5 | CC41: 26844 | CD41: 120.12 | CE41: 30461 | CF41: 30.25 | CG41: 40990 | CH41: 145.3 | CI41: 31560 | CJ41: 1403.4 | CK41: 28912 | CL41: 43.517 | CM41: 40434 | CN41: 0.08 | CO41: 42795 | CP41: 17.24 | CQ41: 36341 | CR41: 351.79 | CS41: 36341 | CT41: 566.61 | CU41: 36341 | CV41: 359.21 | CW41: 36341 | CX41: 276.9181 | CY41: 36341 | CZ41: 319.82 | DA41: 36341 | DB41: 264.93 | DC41: 36341 | DD41: 228.26 | DE41: 36341 | DF41: 216.1 | DG41: 36341 | DH41: 161.45 | DI41: 36341 | DJ41: 157.31 | DK41: 40816 | DL41: 113.25
A42: 29311 | B42: 1.3 | C42: 29311 | D42: 1.4 | E42: 29311 | F42: 10.4 | G42: 29311 | H42: 9 | I42: 26815 | J42: 4.9 | K42: 26815 | L42: 193 | M42: 41455 | N42: 205 | O42: 26815 | P42: 236.3 | Q42: 26815 | R42: 5.9 | S42: 26815 | T42: 3.2 | U42: 26815 | V42: 3.45546 | W42: 28276 | X42: 6.1 | Y42: 26815 | Z42: 8.94 | AA42: 26815 | AB42: 88.403 | AC42: 34880 | AD42: 4.3 | AG42: 26815 | AH42: 64.8 | AM42: 36860 | AN42: 56.2 | AO42: 26815 | AP42: 0.44 | AQ42: 26815 | AR42: 36.6 | AS42: 38321 | AT42: 15.3 | AU42: 35520 | AV42: 12 | AW42: 26815 | AX42: 71.9 | AY42: 26815 | AZ42: 7.4 | BA42: 26815 | BB42: 1931 | BC42: 37407 | BD42: 5.64 | BE42: 34880 | BF42: 0.4 | BG42: 35216 | BH42: 5.7 | BI42: 29006 | BJ42: 14 | BK42: 26815 | BL42: 12 | BM42: 37772 | BN42: 3.1 | BO42: 34150 | BP42: 0.6 | BQ42: 28064 | BR42: 87.1 | BS42: 29737 | BT42: 76.3 | BU42: 25629 | BV42: 89.71 | BW42: 25806 | BX42: 87 | BY42: 26249 | BZ42: 103.91 | CA42: 23650 | CB42: 3.45 | CC42: 26876 | CD42: 120.17 | CE42: 30462 | CF42: 30.31 | CG42: 40991 | CH42: 145.1 | CI42: 31561 | CJ42: 1402 | CK42: 28913 | CL42: 42.547 | CM42: 40435 | CN42: 0.08 | CO42: 42796 | CP42: 20.16 | CQ42: 36433 | CR42: 297.14 | CS42: 36433 | CT42: 594.47 | CU42: 36433 | CV42: 321.55 | CW42: 36433 | CX42: 252.6919 | CY42: 36433 | CZ42: 295.08 | DA42: 36433 | DB42: 251.03 | DC42: 36433 | DD42: 198.76 | DE42: 36433 | DF42: 212.33 | DG42: 36433 | DH42: 151.85 | DI42: 36433 | DJ42: 143.72 | DK42: 40907 | DL42: 130.15
A43: 29402 | B43: -8 | C43: 29402 | D43: -0.8 | E43: 29402 | F43: 8 | G43: 29402 | H43: 9.8 | I43: 26845 | J43: 4.9 | K43: 26845 | L43: 239 | M43: 41486 | N43: 171 | O43: 26845 | P43: 240.5 | Q43: 26845 | R43: 6.2 | S43: 26845 | T43: 3.2 | U43: 26845 | V43: 3.69249 | W43: 28306 | X43: 5.9 | Y43: 26845 | Z43: 8.79 | AA43: 26845 | AB43: 88.2029 | AC43: 34911 | AD43: 3.1 | AG43: 26845 | AH43: 65 | AM43: 36891 | AN43: 54 | AO43: 26845 | AP43: 0.22 | AQ43: 26845 | AR43: 30.4 | AS43: 38352 | AT43: 21.6 | AU43: 35550 | AV43: 11 | AW43: 26845 | AX43: 73.3 | AY43: 26845 | AZ43: 6.3 | BA43: 26845 | BB43: 2051 | BC43: 37437 | BD43: 5.51 | BE43: 34911 | BF43: 0.2 | BG43: 35246 | BH43: 5.4 | BI43: 29036 | BJ43: 12.4 | BK43: 26845 | BL43: 12.4 | BM43: 37802 | BN43: 3.3 | BO43: 34181 | BP43: 0.5 | BQ43: 28125 | BR43: 98.9 | BS43: 29767 | BT43: 73.1 | BU43: 25630 | BV43: 90.23 | BW43: 25811 | BX43: 87.17 | BY43: 26256 | BZ43: 102.95 | CA43: 23742 | CB43: 3.85 | CC43: 26907 | CD43: 106.76 | CE43: 30463 | CF43: 30.19 | CG43: 40994 | CH43: 145.1 | CI43: 31562 | CJ43: 1406.6 | CK43: 28914 | CL43: 42.479 | CM43: 40436 | CN43: 0.08 | CO43: 42797 | CP43: 20.74 | CQ43: 36525 | CR43: 321.72 | CS43: 36525 | CT43: 807.44 | CU43: 36525 | CV43: 326.78 | CW43: 36525 | CX43: 299.3063 | CY43: 36525 | CZ43: 322.81 | DA43: 36525 | DB43: 273.38 | DC43: 36525 | DD43: 208.05 | DE43: 36525 | DF43: 212.72 | DG43: 36525 | DH43: 142.43 | DI43: 36525 | DJ43: 159.96 | DK43: 40998 | DL43: 142.09
A44: 29494 | B44: -0.5 | C44: 29494 | D44: -1.6 | E44: 29494 | F44: 7.1 | G44: 29494 | H44: 9.2 | I44: 26876 | J44: 4.8 | K44: 26876 | L44: 26 | M44: 41517 | N44: 274 | O44: 26876 | P44: 242.8 | Q44: 26876 | R44: 6.4 | S44: 26876 | T44: 3.2 | U44: 26876 | V44: 3.83975 | W44: 28337 | X44: 6 | Y44: 26876 | Z44: 9.33 | AA44: 26876 | AB44: 88.2221 | AC44: 34942 | AD44: 6 | AG44: 26876 | AH44: 57.8 | AM44: 36922 | AN44: 51.6 | AO44: 26876 | AP44: 0.51 | AQ44: 26876 | AR44: 24.8 | AS44: 38383 | AT44: 15.6 | AU44: 35581 | AV44: 10 | AW44: 26876 | AX44: 68.1 | AY44: 26876 | AZ44: 5 | BA44: 26876 | BB44: 1819 | BC44: 37468 | BD44: 5.41 | BE44: 34942 | BF44: 0.4 | BG44: 35277 | BH44: 5.3 | BI44: 29067 | BJ44: 13.7 | BK44: 26876 | BL44: 12.1 | BM44: 37833 | BN44: 3.1 | BO44: 34212 | BP44: 0.2 | BQ44: 28184 | BR44: 97.6 | BS44: 29798 | BT44: 74.1 | BU44: 25631 | BV44: 90.04 | BW44: 25813 | BX44: 86.57 | BY44: 26263 | BZ44: 101.64 | CA44: 23832 | CB44: 4.05 | CC44: 26935 | CD44: 102.97 | CE44: 30467 | CF44: 30.25 | CG44: 41010 | CH44: 147.4 | CI44: 31565 | CJ44: 1414.6 | CK44: 28915 | CL44: 42.784 | CM44: 40437 | CN44: 0.08 | CO44: 42800 | CP44: 20.98 | CQ44: 36616 | CR44: 327.62 | CS44: 36616 | CT44: 916.71 | CU44: 36616 | CV44: 326.26 | CW44: 36616 | CX44: 287.6298 | CY44: 36616 | CZ44: 317.2 | DA44: 36616 | DB44: 269.35 | DC44: 36616 | DD44: 171.55 | DE44: 36616 | DF44: 216.62 | DG44: 36616 | DH44: 151.48 | DI44: 36616 | DJ44: 139.59 | DK44: 41089 | DL44: 146.68
A45: 29586 | B45: 7.7 | C45: 29586 | D45: 0 | E45: 29586 | F45: 9.6 | G45: 29586 | H45: 11 | I45: 26907 | J45: 4.8 | K45: 26907 | L45: 255 | M45: 41547 | N45: -14 | O45: 26907 | P45: 254.8 | Q45: 26907 | R45: 6.1 | S45: 26907 | T45: 3.2 | U45: 26907 | V45: 4.10146 | W45: 28368 | X45: 6.2 | Y45: 26907 | Z45: 7.69 | AA45: 26907 | AB45: 87.8012 | AC45: 34972 | AD45: 9.6 | AG45: 26907 | AH45: 62.7 | AM45: 36950 | AN45: 51.3 | AO45: 26907 | AP45: -0.37 | AQ45: 26907 | AR45: 18.5 | AS45: 38411 | AT45: 17.1 | AU45: 35611 | AV45: 11 | AW45: 26907 | AX45: 68.4 | AY45: 26907 | AZ45: 2.9 | BA45: 26907 | BB45: 1809 | BC45: 37499 | BD45: 5.36 | BE45: 34972 | BF45: 0.7 | BG45: 35308 | BH45: 5.2 | BI45: 29098 | BJ45: 14 | BK45: 26907 | BL45: 11.7 | BM45: 37864 | BN45: 3.8 | BO45: 34242 | BP45: 0.4 | BQ45: 28245 | BR45: 93.1 | BS45: 29829 | BT45: 77.2 | BU45: 25632 | BV45: 90 | BW45: 25820 | BX45: 88.16 | BY45: 26270 | BZ45: 107.26 | CA45: 23923 | CB45: 4.05 | CC45: 26968 | CD45: 100.08 | CE45: 30468 | CF45: 30.33 | CG45: 41011 | CH45: 148.2 | CI45: 31566 | CJ45: 1410.3 | CK45: 28916 | CL45: 42.974 | CM45: 40438 | CN45: 0.08 | CO45: 42801 | CP45: 20.98 | CQ45: 36707 | CR45: 316.56 | CS45: 36707 | CT45: 831.85 | CU45: 36707 | CV45: 401.68 | CW45: 36707 | CX45: 262.2645 | CY45: 36707 | CZ45: 271.99 | DA45: 36707 | DB45: 265.54 | DC45: 36707 | DD45: 193.96 | DE45: 36707 | DF45: 221.76 | DG45: 36707 | DH45: 158.71 | DI45: 36707 | DJ45: 118.08 | DK45: 41180 | DL45: 147.21
A46: 29676 | B46: 8.1 | C46: 29676 | D46: 1.6 | E46: 29676 | F46: 12 | G46: 29676 | H46: 11 | I46: 26937 | J46: 4.8 | K46: 26937 | L46: 108 | M46: 41578 | N46: 128 | O46: 26937 | P46: 248 | Q46: 26937 | R46: 6.3 | S46: 26937 | T46: 3.8 | U46: 26937 | V46: 4.28059 | W46: 28398 | X46: 6.2 | Y46: 26937 | Z46: 7.73 | AA46: 26937 | AB46: 88.2072 | AC46: 35003 | AD46: 4.6 | AG46: 26937 | AH46: 63.5 | AM46: 36981 | AN46: 50.7 | AO46: 26937 | AP46: 0.63 | AQ46: 26937 | AR46: -0.3 | AS46: 38442 | AT46: 24.3 | AU46: 35642 | AV46: 4 | AW46: 26937 | AX46: 70.4 | AY46: 26937 | AZ46: 1.2 | BA46: 26937 | BB46: 1704 | BC46: 37529 | BD46: 5.52 | BE46: 35003 | BF46: -0.6 | BG46: 35338 | BH46: 5.2 | BI46: 29128 | BJ46: 14 | BK46: 26937 | BL46: 11.9 | BM46: 37894 | BN46: 4 | BO46: 34273 | BP46: 0.3 | BQ46: 28306 | BR46: 98.2 | BS46: 29859 | BT46: 73.1 | BU46: 25633 | BV46: 89.44 | BW46: 25827 | BX46: 87.2 | BY46: 26277 | BZ46: 108.81 | CA46: 24015 | CB46: 4.02 | CC46: 26998 | CD46: 94.82 | CE46: 30469 | CF46: 30.4 | CG46: 41012 | CH46: 148.4 | CI46: 31567 | CJ46: 1398.2 | CK46: 28919 | CL46: 43.324 | CM46: 40441 | CN46: 0.08 | CO46: 42802 | CP46: 18.17 | CQ46: 36798 | CR46: 390.29 | CS46: 36798 | CT46: 715.78 | CU46: 36798 | CV46: 399.7 | CW46: 36798 | CX46: 248.4063 | CY46: 36798 | CZ46: 241.62 | DA46: 36798 | DB46: 288.13 | DC46: 36798 | DD46: 197.23 | DE46: 36798 | DF46: 239.58 | DG46: 36798 | DH46: 209.32 | DI46: 36798 | DJ46: 108.23 | DK46: 41274 | DL46: 151.26
A47: 29767 | B47: -2.9 | C47: 29767 | D47: 3 | E47: 29767 | F47: 13.1 | G47: 29767 | H47: 7.7 | I47: 26968 | J47: 4.6 | K47: 26968 | L47: 331 | M47: 41608 | N47: 307 | O47: 26968 | P47: 241.5 | Q47: 26968 | R47: 6 | S47: 26968 | T47: 4.3 | U47: 26968 | V47: 4.62303 | W47: 28429 | X47: 6.4 | Y47: 26968 | Z47: 7.2 | AA47: 26968 | AB47: 88.6195 | AC47: 35033 | AD47: 4.4 | AG47: 26968 | AH47: 66.2 | AM47: 37011 | AN47: 48.3 | AO47: 26968 | AP47: 1.04 | AQ47: 26968 | AR47: 9.8 | AS47: 38472 | AT47: 8.3 | AU47: 35673 | AV47: 5 | AW47: 26968 | AX47: 69.9 | AY47: 26968 | AZ47: 0 | BA47: 26968 | BB47: 1411 | BC47: 37560 | BD47: 5.68 | BE47: 35033 | BF47: 1.2 | BG47: 35369 | BH47: 6.8 | BI47: 29159 | BJ47: 12.7 | BK47: 26968 | BL47: 10.8 | BM47: 37925 | BN47: 3.8 | BO47: 34303 | BP47: 0.3 | BQ47: 28337 | BR47: 97.5 | BS47: 29890 | BT47: 70.3 | BU47: 25636 | BV47: 88.51 | BW47: 25834 | BX47: 88.38 | BY47: 26284 | BZ47: 110.52 | CA47: 24107 | CB47: 4.32 | CC47: 27029 | CD47: 106.72 | CE47: 30470 | CF47: 30.36 | CG47: 41015 | CH47: 148 | CI47: 31568 | CJ47: 1409.9 | CK47: 28920 | CL47: 43.279 | CM47: 40442 | CN47: 0.08 | CO47: 42803 | CP47: 18.72 | CQ47: 36889 | CR47: 397.09 | CS47: 36889 | CT47: 476.64 | CU47: 36889 | CV47: 442.92 | CW47: 36889 | CX47: 237.2528 | CY47: 36889 | CZ47: 194.76 | DA47: 36889 | DB47: 285.77 | DC47: 36889 | DD47: 238.15 | DE47: 36889 | DF47: 240.87 | DG47: 36889 | DH47: 216.03 | DI47: 36889 | DJ47: 131.61 | DK47: 41362 | DL47: 159.29
A48: 29859 | B48: 4.9 | C48: 29859 | D48: 4.3 | E48: 29859 | F48: 14.1 | G48: 29859 | H48: 8 | I48: 26998 | J48: 4.8 | K48: 26998 | L48: 313 | M48: 41639 | N48: 246 | O48: 26998 | P48: 256.3 | Q48: 26998 | R48: 6.3 | S48: 26998 | T48: 4.5 | U48: 26998 | V48: 4.85212 | W48: 28459 | X48: 6.3 | Y48: 26998 | Z48: 6.44 | AA48: 26998 | AB48: 88.7326 | AC48: 35064 | AD48: 5.7 | AG48: 26998 | AH48: 68.1 | AM48: 37042 | AN48: 49 | AO48: 26998 | AP48: 0.78 | AQ48: 26998 | AR48: 15.4 | AS48: 38503 | AT48: -4.9 | AU48: 35703 | AV48: 23 | AW48: 26998 | AX48: 80.9 | AY48: 26998 | AZ48: -1.4 | BA48: 26998 | BB48: 1402 | BC48: 37590 | BD48: 5.73 | BE48: 35064 | BF48: 0.9 | BG48: 35399 | BH48: 6 | BI48: 29189 | BJ48: 12.7 | BK48: 26998 | BL48: 10.5 | BM48: 37955 | BN48: 4.1 | BO48: 34334 | BP48: 0.4 | BQ48: 28368 | BR48: 98.7 | BS48: 29920 | BT48: 62.5 | BU48: 25637 | BV48: 88.75 | BW48: 25841 | BX48: 89.79 | BY48: 26291 | BZ48: 111.94 | CA48: 24197 | CB48: 4.66 | CC48: 27060 | CD48: 129.19 | CE48: 30473 | CF48: 30.35 | CG48: 41017 | CH48: 148 | CI48: 31569 | CJ48: 1433.4 | CK48: 28921 | CL48: 43.645 | CM48: 40443 | CN48: 0.08 | CO48: 42804 | CP48: 20.01 | CQ48: 36980 | CR48: 357.39 | CS48: 36980 | CT48: 353.1 | CU48: 36980 | CV48: 376.44 | CW48: 36980 | CX48: 236.7704 | CY48: 36980 | CZ48: 192.48 | DA48: 36980 | DB48: 255.02 | DC48: 36980 | DD48: 213.79 | DE48: 36980 | DF48: 224.76 | DG48: 36980 | DH48: 199.51 | DI48: 36980 | DJ48: 123.42 | DK48: 41453 | DL48: 155.23
A49: 29951 | B49: -4.3 | C49: 29951 | D49: 1.3 | E49: 29951 | F49: 9.9 | G49: 29951 | H49: 6.8 | I49: 27029 | J49: 4.9 | K49: 27029 | L49: 111 | M49: 41670 | N49: 139 | O49: 27029 | P49: 291 | Q49: 27029 | R49: 6 | S49: 27029 | T49: 4.7 | U49: 27029 | V49: 5.11827 | W49: 28490 | X49: 6.2 | Y49: 27029 | Z49: 4.98 | AA49: 27029 | AB49: 88.2092 | AC49: 35095 | AD49: 4.9 | AG49: 27029 | AH49: 63.6 | AM49: 37072 | AN49: 50.1 | AO49: 27029 | AP49: -0.41 | AQ49: 27029 | AR49: 8 | AS49: 38533 | AT49: 7.8 | AU49: 35734 | AV49: 14 | AW49: 27029 | AX49: 74.3 | AY49: 27029 | AZ49: -3.6 | BA49: 27029 | BB49: 1288 | BC49: 37621 | BD49: 5.97 | BE49: 35095 | BF49: -1.2 | BG49: 35430 | BH49: 5.6 | BI49: 29220 | BJ49: 13.2 | BK49: 27029 | BL49: 10.4 | BM49: 37986 | BN49: 3.5 | BO49: 34365 | BP49: -0.4 | BQ49: 28398 | BR49: 96.7 | BS49: 29951 | BT49: 64.3 | BU49: 25638 | BV49: 88.69 | BW49: 25848 | BX49: 92.01 | BY49: 26298 | BZ49: 114.12 | CA49: 24288 | CB49: 5.17 | CC49: 27088 | CD49: 150.23 | CE49: 30474 | CF49: 30.59 | CG49: 41018 | CH49: 147.7 | CI49: 31572 | CJ49: 1427.8 | CK49: 28922 | CL49: 44.096 | CM49: 40444 | CN49: 0.08 | CO49: 42807 | CP49: 30.53 | CQ49: 37071 | CR49: 383.87 | CS49: 37071 | CT49: 396.69 | CU49: 37071 | CV49: 372.25 | CW49: 37071 | CX49: 259.9792 | CY49: 37071 | CZ49: 188.1 | DA49: 37071 | DB49: 282.65 | DC49: 37071 | DD49: 208.55 | DE49: 37071 | DF49: 230.56 | DG49: 37071 | DH49: 186.9 | DI49: 37071 | DJ49: 135.94 | DK49: 41547 | DL49: 150.14
